Workbook

Sheet Ranking
A1: Gracz | B1: Punkty
A2: Marta | B2: =Marta!D74 -> 6
A3: Dominika | B3: =Dominika!D74 -> 4
A4: Ela G | B4: ='Ela G'!D74 -> 3
A5: Kasia K | B5: ='Kasia K'!D74 -> 3
A6: Karol K | B6: ='Karol K'!D74 -> 3
A7: Marzena | B7: =Marzena!D74 -> 3
A8: Paweł J | B8: ='Paweł J'!D74 -> 3
A9: Paweł P | B9: ='Paweł P'!D74 -> 3
A10: Paulina | B10: =Paulina!D74 -> 3
A11: Maja | B11: =Maja!D74 -> 2
A12: Karolek Asi | B12: ='Karolek Asi'!D74 -> 1
A13: Janusz Soko | B13: ='Janusz Soko'!D74 -> 1
A14: Michał Klaudii | B14: ='Michał Klaudii'!D74 -> 1
A15: Monika Soko | B15: ='Monika Soko'!D74 -> 1
A16: Adam | B16: =Adam!D74 -> 1
A17: Ola L | B17: ='Ola L'!D74 -> 1
A18: Ola R | B18: ='Ola R'!D74 -> 1
A19: Anita | B19: =Anita!D74 -> 1
A20: Agata | B20: =Agata!D74 -> 1
A21: Bartosz | B21: =Bartosz!D74 -> 1
A22: Ela S | B22: ='Ela S'!D74 -> 1
A23: Kasia D | B23: ='Kasia D'!D74 -> 1
A24: Klaudia | B24: =Klaudia!D74 -> 1
A25: Magdalena | B25: =Magdalena!D74 -> 1
A26: Monika SP | B26: ='Monika SP'!D74 -> 1
A27: Przemek | B27: =Przemek!D74 -> 1
A28: Sylwia G | B28: ='Sylwia G'!D74 -> 1
A29: Sylwia CRS | B29: ='Sylwia CRS'!D74 -> 1
A30: Vadym | B30: =Vadym!D74 -> 1
A31: Asia | B31: =Asia!D74 -> 0

Sheet Typy_Zbiorcze
A1: Gracz | B1: Suma punktów | C1: Meksyk-RPA | D1: Korea Południowa-Czechy | E1: Kanada-Bośnia i Hercegowina | F1: USA-Paragwaj | G1: Katar-Szwajcaria | H1: Brazylia-Maroko | I1: Haiti-Szkocja | J1: Australia-Turcja | K1: Niemcy-Curacao | L1: Holandia-Japonia | M1: Wybrzeże Kości Słoniowej-Ekwador | N1: Szwecja-Tunezja | O1: Hiszpania-Republika Zielonego Przylądka | P1: Belgia-Egipt | Q1: Arabia Saudyjska-Urugwaj | R1: Iran-Nowa Zelandia | S1: Francja-Senegal | T1: Irak-Norwegia | U1: Argentyna-Algieria | V1: Austria-Jordania | W1: Portugalia-DR Konga | X1: Anglia-Chorwacja | Y1: Ghana-Panama | Z1: Uzbekistan-Kolumbia | AA1: Czechy-RPA | AB1: Szwajcaria-Bośnia i Hercegowina | AC1: Kanada-Katar | AD1: Meksyk-Korea Południowa | AE1: USA-Australia | AF1: Szkocja-Maroko | AG1: Brazylia-Haiti | AH1: Turcja-Paragwaj | AI1: Holandia-Szwecja | AJ1: Niemcy-Wybrzeże Kości Słoniowej | AK1: Ekwador-Curacao | AL1: Tunezja-Japonia | AM1: Hiszpania-Arabia Saudyjska | AN1: Belgia-Iran | AO1: Urugwaj-Republika Zielonego Przylądka | AP1: Nowa Zelandia-Egipt | AQ1: Argentyna-Austria | AR1: Francja-Irak | AS1: Norwegia-Senegal | AT1: Jordania-Algieria | AU1: Portugalia-Uzbekistan | AV1: Anglia-Ghana | AW1: Panama-Chorwacja | AX1: Kolumbia-DR Konga | AY1: Szwajcaria-Kanada | AZ1: Bośnia i Hercegowina-Katar | BA1: Szkocja-Brazylia | BB1: Maroko-Haiti | BC1: Czechy-Meksyk | BD1: RPA-Korea Południowa | BE1: Curacao-Wybrzeże Kości Słoniowej | BF1: Ekwador-Niemcy | BG1: Japonia-Szwecja | BH1: Tunezja-Holandia | BI1: Turcja-USA | BJ1: Paragwaj-Australia | BK1: Norwegia-Francja | BL1: Senegal-Irak | BM1: Republika Zielonego Przylądka-Arabia Saudyjska | BN1: Urugwaj-Hiszpania | BO1: Egipt-Iran | BP1: Nowa Zelandia-Belgia | BQ1: Panama-Anglia | BR1: Chorwacja-Ghana | BS1: Kolumbia-Portugalia | BT1: DR Konga-Uzbekistan | BU1: Algieria-Austria | BV1: Jordania-Argentyna | BW1: Suma punktów
A2: Marta | B2: =BW2 -> 6 | C2: =Marta!B2 -> 2-0 | D2: =Marta!B3 -> 2-1 | E2: =Marta!B4 -> 1-0 | F2: =Marta!B5 -> 1-1 | G2: =Marta!B6 -> 0-3 | H2: =Marta!B7 -> 1-1 | I2: =Marta!B8 -> 0-4 | J2: =Marta!B9 -> 0-4 | K2: =Marta!B10 -> 7-0 | L2: =Marta!B11 -> 1-1 | M2: =Marta!B12 -> 2-1 | N2: =Marta!B13 -> 1-0 | O2: =Marta!B14 -> 6-0 | P2: =Marta!B15 -> 2-0 | Q2: =Marta!B16 -> 1-1 | R2: =Marta!B17 -> 0-0 | S2: =Marta!B18 -> 3-0 | T2: =Marta!B19 -> 0-4 | U2: =Marta!B20 -> 3-1 | V2: =Marta!B21 -> 2-0 | W2: =Marta!B22 -> 4-0 | X2: =Marta!B23 -> 1-1 | Y2: =Marta!B24 -> 2-0 | Z2: =Marta!B25 -> 0-2 | AA2: =Marta!B26 -> 1-1 | AB2: =Marta!B27 -> 2-0 | AC2: =Marta!B28 -> 3-0 | AD2: =Marta!B29 -> 0-0 | AE2: =Marta!B30 -> 1-0 | AF2: =Marta!B31 -> 0-1 | AG2: =Marta!B32 -> 5-0 | AH2: =Marta!B33 -> 2-0 | AI2: =Marta!B34 -> 3-1 | AJ2: =Marta!B35 -> 2-2 | AK2: =Marta!B36 -> 3-0 | AL2: =Marta!B37 -> 0-2 | AM2: =Marta!B38 -> 2-0 | AN2: =Marta!B39 -> 3-1 | AO2: =Marta!B40 -> 3-0 | AP2: =Marta!B41 -> 0-2 | AQ2: =Marta!B42 -> 2-0 | AR2: =Marta!B43 -> 3-0 | AS2: =Marta!B44 -> 1-0 | AT2: =Marta!B45 -> 0-0 | AU2: =Marta!B46 -> 3-0 | AV2: =Marta!B47 -> 2-1 | AW2: =Marta!B48 -> 0-3 | AX2: =Marta!B49 -> 2-0 | AY2: =Marta!B50 -> 1-1 | AZ2: =Marta!B51 -> 1-0 | BA2: =Marta!B52 -> 0-2 | BB2: =Marta!B53 -> 3-0 | BC2: =Marta!B54 -> 1-1 | BD2: =Marta!B55 -> 0-2 | BE2: =Marta!B56 -> 0-2 | BF2: =Marta!B57 -> 1-2 | BG2: =Marta!B58 -> 2-1 | BH2: =Marta!B59 -> 0-3 | BI2: =Marta!B60 -> 1-0 | BJ2: =Marta!B61 -> 1-0 | BK2: =Marta!B62 -> 1-1 | BL2: =Marta!B63 -> 2-1 | BM2: =Marta!B64 -> 0-2 | BN2: =Marta!B65 -> 1-1 | BO2: =Marta!B66 -> 2-0 | BP2: =Marta!B67 -> 0-4 | BQ2: =Marta!B68 -> 0-3 | BR2: =Marta!B69 -> 1-1 | BS2: =Marta!B70 -> 0-0 | BT2: =Marta!B71 -> 1-1 | BU2: =Marta!B72 -> 0-1 | BV2: =Marta!B73 -> 0-4 | BW2: =Marta!D74 -> 6
A3: Dominika | B3: =BW3 -> 4 | C3: =Dominika!B2 -> 3:0 | D3: =Dominika!B3 -> 2:1 | E3: =Dominika!B4 -> 3:0 | F3: =Dominika!B5 -> 1:0 | G3: =Dominika!B6 -> 3:0 | H3: =Dominika!B7 -> 3:2 | I3: =Dominika!B8 -> 2:0 | J3: =Dominika!B9 -> 1:0 | K3: =Dominika!B10 -> 4:0 | L3: =Dominika!B11 -> 1:0 | M3: =Dominika!B12 -> 2:0 | N3: =Dominika!B13 -> 0:0 | O3: =Dominika!B14 -> 4:0 | P3: =Dominika!B15 -> 2:1 | Q3: =Dominika!B16 -> 1:1 | R3: =Dominika!B17 -> 1:0 | S3: =Dominika!B18 -> 3:0 | T3: =Dominika!B19 -> 2:0 | U3: =Dominika!B20 -> 3:1 | V3: =Dominika!B21 -> 1:0 | W3: =Dominika!B22 -> 3:0 | X3: =Dominika!B23 -> 1:1 | Y3: =Dominika!B24 -> 1:0 | Z3: =Dominika!B25 -> 1:0 | AA3: =Dominika!B26 -> 2:0 | AB3: =Dominika!B27 -> 3:0 | AC3: =Dominika!B28 -> 2:0 | AD3: =Dominika!B29 -> 2:1 | AE3: =Dominika!B30 -> 2:2 | AF3: =Dominika!B31 -> 2:1 | AG3: =Dominika!B32 -> 5:0 | AH3: =Dominika!B33 -> 1:0 | AI3: =Dominika!B34 -> 2:0 | AJ3: =Dominika!B35 -> 3:0 | AK3: =Dominika!B36 -> 2:0 | AL3: =Dominika!B37 -> 1:0 | AM3: =Dominika!B38 -> 3:0 | AN3: =Dominika!B39 -> 2:1 | AO3: =Dominika!B40 -> 1:1 | AP3: =Dominika!B41 -> 0:2 | AQ3: =Dominika!B42 -> 3:1 | AR3: =Dominika!B43 -> 4:0 | AS3: =Dominika!B44 -> 2:2 | AT3: =Dominika!B45 -> 0:1 | AU3: =Dominika!B46 -> 3:0 | AV3: =Dominika!B47 -> 1:2 | AW3: =Dominika!B48 -> 3:1 | AX3: =Dominika!B49 -> 0:0 | AY3: =Dominika!B50 -> 1:0 | AZ3: =Dominika!B51 -> 1:2 | BA3: =Dominika!B52 -> 3:1 | BB3: =Dominika!B53 -> 2:0 | BC3: =Dominika!B54 -> 0:2 | BD3: =Dominika!B55 -> 2:1 | BE3: =Dominika!B56 -> 0:1 | BF3: =Dominika!B57 -> 2:3 | BG3: =Dominika!B58 -> 2:0 | BH3: =Dominika!B59 -> 2:0 | BI3: =Dominika!B60 -> 1:2 | BJ3: =Dominika!B61 -> 1:1 | BK3: =Dominika!B62 -> 1:3 | BL3: =Dominika!B63 -> 1:0 | BM3: =Dominika!B64 -> 0:1 | BN3: =Dominika!B65 -> 3:0 | BO3: =Dominika!B66 -> 2:1 | BP3: =Dominika!B67 -> 0:2 | BQ3: =Dominika!B68 -> 0:3 | BR3: =Dominika!B69 -> 2:0 | BS3: =Dominika!B70 -> 2:0 | BT3: =Dominika!B71 -> 0:1 | BU3: =Dominika!B72 -> 0:0 | BV3: =Dominika!B73 -> 0:2 | BW3: =Dominika!D74 -> 4
A4: Ela G | B4: =BW4 -> 3 | C4: ='Ela G'!B2 -> 2:0 | D4: ='Ela G'!B3 -> 1:2 | E4: ='Ela G'!B4 -> 1:1 | F4: ='Ela G'!B5 -> 2:2 | G4: ='Ela G'!B6 -> 0:2 | H4: ='Ela G'!B7 -> 2:0 | I4: ='Ela G'!B8 -> 0:3 | J4: ='Ela G'!B9 -> 1:1 | K4: ='Ela G'!B10 -> 5:0 | L4: ='Ela G'!B11 -> 2:1 | M4: ='Ela G'!B12 -> 2:1 | N4: ='Ela G'!B13 -> 2:0 | O4: ='Ela G'!B14 -> 6:0 | P4: ='Ela G'!B15 -> 2:0 | Q4: ='Ela G'!B16 -> 0:3 | R4: ='Ela G'!B17 -> 1:2 | S4: ='Ela G'!B18 -> 2:1 | T4: ='Ela G'!B19 -> 0:2 | U4: ='Ela G'!B20 -> 3:1 | V4: ='Ela G'!B21 -> 2:0 | W4: ='Ela G'!B22 -> 3:1 | X4: ='Ela G'!B23 -> 2:1 | Y4: ='Ela G'!B24 -> 2:0 | Z4: ='Ela G'!B25 -> 1:3 | AA4: ='Ela G'!B26 -> 2:1 | AB4: ='Ela G'!B27 -> 2:1 | AC4: ='Ela G'!B28 -> 1:1 | AD4: ='Ela G'!B29 -> 2:1 | AE4: ='Ela G'!B30 -> 2:1 | AF4: ='Ela G'!B31 -> 0:2 | AG4: ='Ela G'!B32 -> 4:0 | AH4: ='Ela G'!B33 -> 2:2 | AI4: ='Ela G'!B34 -> 2:1 | AJ4: ='Ela G'!B35 -> 3:1 | AK4: ='Ela G'!B36 -> 2:1 | AL4: ='Ela G'!B37 -> 1:2 | AM4: ='Ela G'!B38 -> 3:1 | AN4: ='Ela G'!B39 -> 2:0 | AO4: ='Ela G'!B40 -> 4:1 | AP4: ='Ela G'!B41 -> 1:1 | AQ4: ='Ela G'!B42 -> 2:0 | AR4: ='Ela G'!B43 -> 3:0 | AS4: ='Ela G'!B44 -> 2:2 | AT4: ='Ela G'!B45 -> 0:2 | AU4: ='Ela G'!B46 -> 3:0 | AV4: ='Ela G'!B47 -> 2:2 | AW4: ='Ela G'!B48 -> 1:2 | AX4: ='Ela G'!B49 -> 3:1 | AY4: ='Ela G'!B50 -> 1:1 | AZ4: ='Ela G'!B51 -> 1:1 | BA4: ='Ela G'!B52 -> 0:2 | BB4: ='Ela G'!B53 -> 3:0 | BC4: ='Ela G'!B54 -> 1:3 | BD4: ='Ela G'!B55 -> 1:1 | BE4: ='Ela G'!B56 -> 0:2 | BF4: ='Ela G'!B57 -> 1:3 | BG4: ='Ela G'!B58 -> 1:1 | BH4: ='Ela G'!B59 -> 1:2 | BI4: ='Ela G'!B60 -> 1:2 | BJ4: ='Ela G'!B61 -> 1:1 | BK4: ='Ela G'!B62 -> 0:2 | BL4: ='Ela G'!B63 -> 2:0 | BM4: ='Ela G'!B64 -> 1:2 | BN4: ='Ela G'!B65 -> 1:1 | BO4: ='Ela G'!B66 -> 0:1 | BP4: ='Ela G'!B67 -> 0:2 | BQ4: ='Ela G'!B68 -> 0:3 | BR4: ='Ela G'!B69 -> 1:1 | BS4: ='Ela G'!B70 -> 1:1 | BT4: ='Ela G'!B71 -> 1:1 | BU4: ='Ela G'!B72 -> 1:1 | BV4: ='Ela G'!B73 -> 0:3 | BW4: ='Ela G'!D74 -> 3
A5: Kasia K | B5: =BW5 -> 3 | C5: ='Kasia K'!B2 -> 2:0 | D5: ='Kasia K'!B3 -> 1:1 | E5: ='Kasia K'!B4 -> 1:1 | F5: ='Kasia K'!B5 -> 1:0 | G5: ='Kasia K'!B6 -> 0:2 | H5: ='Kasia K'!B7 -> 3:1 | I5: ='Kasia K'!B8 -> 0:1 | J5: ='Kasia K'!B9 -> 1:2 | K5: ='Kasia K'!B10 -> 5:0 | L5: ='Kasia K'!B11 -> 2:1 | M5: ='Kasia K'!B12 -> 1:1 | N5: ='Kasia K'!B13 -> 2:0 | O5: ='Kasia K'!B14 -> 3:1 | P5: ='Kasia K'!B15 -> 1:1 | Q5: ='Kasia K'!B16 -> 0:1 | R5: ='Kasia K'!B17 -> 2:0 | S5: ='Kasia K'!B18 -> 3:1 | T5: ='Kasia K'!B19 -> 0:2 | U5: ='Kasia K'!B20 -> 3:1 | V5: ='Kasia K'!B21 -> 2:0 | W5: ='Kasia K'!B22 -> 3:1 | X5: ='Kasia K'!B23 -> 2:1 | Y5: ='Kasia K'!B24 -> 2:0 | Z5: ='Kasia K'!B25 -> 0:2 | AA5: ='Kasia K'!B26 -> 1:0 | AB5: ='Kasia K'!B27 -> 1:1 | AC5: ='Kasia K'!B28 -> 1:0 | AD5: ='Kasia K'!B29 -> 1:1 | AE5: ='Kasia K'!B30 -> 2:1 | AF5: ='Kasia K'!B31 -> 1:1 | AG5: ='Kasia K'!B32 -> 4:0 | AH5: ='Kasia K'!B33 -> 1:1 | AI5: ='Kasia K'!B34 -> 1:0 | AJ5: ='Kasia K'!B35 -> 2:2 | AK5: ='Kasia K'!B36 -> 2:0 | AL5: ='Kasia K'!B37 -> 1:1 | AM5: ='Kasia K'!B38 -> 3:1 | AN5: ='Kasia K'!B39 -> 1:0 | AO5: ='Kasia K'!B40 -> 2:0 | AP5: ='Kasia K'!B41 -> 0:1 | AQ5: ='Kasia K'!B42 -> 1:1 | AR5: ='Kasia K'!B43 -> 3:0 | AS5: ='Kasia K'!B44 -> 1:1 | AT5: ='Kasia K'!B45 -> 0:0 | AU5: ='Kasia K'!B46 -> 2:0 | AV5: ='Kasia K'!B47 -> 2:0 | AW5: ='Kasia K'!B48 -> 0:2 | AX5: ='Kasia K'!B49 -> 2:0 | AY5: ='Kasia K'!B50 -> 1:1 | AZ5: ='Kasia K'!B51 -> 2:0 | BA5: ='Kasia K'!B52 -> 1:2 | BB5: ='Kasia K'!B53 -> 2:0 | BC5: ='Kasia K'!B54 -> 0:0 | BD5: ='Kasia K'!B55 -> 0:1 | BE5: ='Kasia K'!B56 -> 0:2 | BF5: ='Kasia K'!B57 -> 1:1 | BG5: ='Kasia K'!B58 -> 0:0 | BH5: ='Kasia K'!B59 -> 0:2 | BI5: ='Kasia K'!B60 -> 2:2 | BJ5: ='Kasia K'!B61 -> 1:1 | BK5: ='Kasia K'!B62 -> 1:2 | BL5: ='Kasia K'!B63 -> 2:0 | BM5: ='Kasia K'!B64 -> 0:0 | BN5: ='Kasia K'!B65 -> 2:1 | BO5: ='Kasia K'!B66 -> 1:1 | BP5: ='Kasia K'!B67 -> 0:2 | BQ5: ='Kasia K'!B68 -> 0:3 | BR5: ='Kasia K'!B69 -> 1:1 | BS5: ='Kasia K'!B70 -> 2:2 | BT5: ='Kasia K'!B71 -> 1:1 | BU5: ='Kasia K'!B72 -> 0:1 | BV5: ='Kasia K'!B73 -> 0:2 | BW5: ='Kasia K'!D74 -> 3
A6: Karol K | B6: =BW6 -> 3 | C6: ='Karol K'!B2 -> 2:0 | D6: ='Karol K'!B3 -> 1:1 | E6: ='Karol K'!B4 -> 2:1 | F6: ='Karol K'!B5 -> 2:1 | G6: ='Karol K'!B6 -> 0:2 | H6: ='Karol K'!B7 -> 2:1 | I6: ='Karol K'!B8 -> 0:2 | J6: ='Karol K'!B9 -> 1:1 | K6: ='Karol K'!B10 -> 4:0 | L6: ='Karol K'!B11 -> 2:1 | M6: ='Karol K'!B12 -> 1:1 | N6: ='Karol K'!B13 -> 2:0 | O6: ='Karol K'!B14 -> 3:0 | P6: ='Karol K'!B15 -> 2:1 | Q6: ='Karol K'!B16 -> 0:2 | R6: ='Karol K'!B17 -> 2:0 | S6: ='Karol K'!B18 -> 3:1 | T6: ='Karol K'!B19 -> 1:2 | U6: ='Karol K'!B20 -> 3:0 | V6: ='Karol K'!B21 -> 2:0 | W6: ='Karol K'!B22 -> 3:0 | X6: ='Karol K'!B23 -> 2:1 | Y6: ='Karol K'!B24 -> 2:1 | Z6: ='Karol K'!B25 -> 0:2 | AA6: ='Karol K'!B26 -> 2:0 | AB6: ='Karol K'!B27 -> 2:1 | AC6: ='Karol K'!B28 -> 2:0 | AD6: ='Karol K'!B29 -> 1:1 | AE6: ='Karol K'!B30 -> 2:0 | AF6: ='Karol K'!B31 -> 1:1 | AG6: ='Karol K'!B32 -> 4:0 | AH6: ='Karol K'!B33 -> 1:1 | AI6: ='Karol K'!B34 -> 2:1 | AJ6: ='Karol K'!B35 -> 2:0 | AK6: ='Karol K'!B36 -> 2:0 | AL6: ='Karol K'!B37 -> 1:1 | AM6: ='Karol K'!B38 -> 3:0 | AN6: ='Karol K'!B39 -> 3:1 | AO6: ='Karol K'!B40 -> 2:0 | AP6: ='Karol K'!B41 -> 0:1 | AQ6: ='Karol K'!B42 -> 2:0 | AR6: ='Karol K'!B43 -> 3:0 | AS6: ='Karol K'!B44 -> 1:1 | AT6: ='Karol K'!B45 -> 0:2 | AU6: ='Karol K'!B46 -> 3:0 | AV6: ='Karol K'!B47 -> 2:1 | AW6: ='Karol K'!B48 -> 0:2 | AX6: ='Karol K'!B49 -> 3:0 | AY6: ='Karol K'!B50 -> 1:1 | AZ6: ='Karol K'!B51 -> 2:1 | BA6: ='Karol K'!B52 -> 1:3 | BB6: ='Karol K'!B53 -> 2:0 | BC6: ='Karol K'!B54 -> 1:1 | BD6: ='Karol K'!B55 -> 0:2 | BE6: ='Karol K'!B56 -> 0:2 | BF6: ='Karol K'!B57 -> 1:2 | BG6: ='Karol K'!B58 -> 1:1 | BH6: ='Karol K'!B59 -> 0:2 | BI6: ='Karol K'!B60 -> 1:2 | BJ6: ='Karol K'!B61 -> 1:1 | BK6: ='Karol K'!B62 -> 1:2 | BL6: ='Karol K'!B63 -> 2:0 | BM6: ='Karol K'!B64 -> 1:1 | BN6: ='Karol K'!B65 -> 1:2 | BO6: ='Karol K'!B66 -> 1:1 | BP6: ='Karol K'!B67 -> 0:3 | BQ6: ='Karol K'!B68 -> 0:3 | BR6: ='Karol K'!B69 -> 2:1 | BS6: ='Karol K'!B70 -> 1:2 | BT6: ='Karol K'!B71 -> 0:1 | BU6: ='Karol K'!B72 -> 1:1 | BV6: ='Karol K'!B73 -> 0:3 | BW6: ='Karol K'!D74 -> 3
A7: Marzena | B7: =BW7 -> 3 | C7: =Marzena!B2 -> 2:0 | D7: =Marzena!B3 -> 1:1 | E7: =Marzena!B4 -> 0:1 | F7: =Marzena!B5 -> 1:2 | G7: =Marzena!B6 -> 0:2 | H7: =Marzena!B7 -> 1:1 | I7: =Marzena!B8 -> 0:2 | J7: =Marzena!B9 -> 0:1 | K7: =Marzena!B10 -> 3:0 | L7: =Marzena!B11 -> 2:0 | M7: =Marzena!B12 -> 1:1 | N7: =Marzena!B13 -> 2:1 | O7: =Marzena!B14 -> 2:0 | P7: =Marzena!B15 -> 3:0 | Q7: =Marzena!B16 -> 1:2 | R7: =Marzena!B17 -> 2:1 | S7: =Marzena!B18 -> 2:1 | T7: =Marzena!B19 -> 0:2 | U7: =Marzena!B20 -> 1:0 | V7: =Marzena!B21 -> 3:1 | W7: =Marzena!B22 -> 3:0 | X7: =Marzena!B23 -> 1:1 | Y7: =Marzena!B24 -> 2:0 | Z7: =Marzena!B25 -> 1:2 | AA7: =Marzena!B26 -> 2:0 | AB7: =Marzena!B27 -> 3:1 | AC7: =Marzena!B28 -> 1:1 | AD7: =Marzena!B29 -> 2:1 | AE7: =Marzena!B30 -> 2:0 | AF7: =Marzena!B31 -> 1:2 | AG7: =Marzena!B32 -> 3:0 | AH7: =Marzena!B33 -> 2:1 | AI7: =Marzena!B34 -> 1:0 | AJ7: =Marzena!B35 -> 2:0 | AK7: =Marzena!B36 -> 1:0 | AL7: =Marzena!B37 -> 1:1 | AM7: =Marzena!B38 -> 3:1 | AN7: =Marzena!B39 -> 2:0 | AO7: =Marzena!B40 -> 2:0 | AP7: =Marzena!B41 -> 2:3 | AQ7: =Marzena!B42 -> 2:0 | AR7: =Marzena!B43 -> 2:0 | AS7: =Marzena!B44 -> 2:1 | AT7: =Marzena!B45 -> 1:2 | AU7: =Marzena!B46 -> 4:1 | AV7: =Marzena!B47 -> 2:1 | AW7: =Marzena!B48 -> 0:1 | AX7: =Marzena!B49 -> 1:1 | AY7: =Marzena!B50 -> 1:1 | AZ7: =Marzena!B51 -> 1:0 | BA7: =Marzena!B52 -> 0:2 | BB7: =Marzena!B53 -> 4:1 | BC7: =Marzena!B54 -> 1:1 | BD7: =Marzena!B55 -> 2:1 | BE7: =Marzena!B56 -> 1:3 | BF7: =Marzena!B57 -> 0:2 | BG7: =Marzena!B58 -> 0:1 | BH7: =Marzena!B59 -> 1:2 | BI7: =Marzena!B60 -> 1:1 | BJ7: =Marzena!B61 -> 2:2 | BK7: =Marzena!B62 -> 1:1 | BL7: =Marzena!B63 -> 2:0 | BM7: =Marzena!B64 -> 1:0 | BN7: =Marzena!B65 -> 1:1 | BO7: =Marzena!B66 -> 0:2 | BP7: =Marzena!B67 -> 1:2 | BQ7: =Marzena!B68 -> 0:2 | BR7: =Marzena!B69 -> 1:1 | BS7: =Marzena!B70 -> 2:2 | BT7: =Marzena!B71 -> 2:1 | BU7: =Marzena!B72 -> 1:1 | BV7: =Marzena!B73 -> 0:3 | BW7: =Marzena!D74 -> 3
A8: Paweł J | B8: =BW8 -> 3 | C8: ='Paweł J'!B2 -> 2:0 | D8: ='Paweł J'!B3 -> 1:1 | E8: ='Paweł J'!B4 -> 2:1 | F8: ='Paweł J'!B5 -> 0:0 | G8: ='Paweł J'!B6 -> 0:2 | H8: ='Paweł J'!B7 -> 3:1 | I8: ='Paweł J'!B8 -> 1:1 | J8: ='Paweł J'!B9 -> 0:1 | K8: ='Paweł J'!B10 -> 4:0 | L8: ='Paweł J'!B11 -> 3:0 | M8: ='Paweł J'!B12 -> 1:1 | N8: ='Paweł J'!B13 -> 1:0 | O8: ='Paweł J'!B14 -> 5:0 | P8: ='Paweł J'!B15 -> 1:1 | Q8: ='Paweł J'!B16 -> 0:2 | R8: ='Paweł J'!B17 -> 3:1 | S8: ='Paweł J'!B18 -> 3:1 | T8: ='Paweł J'!B19 -> 0:2 | U8: ='Paweł J'!B20 -> 2:0 | V8: ='Paweł J'!B21 -> 2:0 | W8: ='Paweł J'!B22 -> 3:0 | X8: ='Paweł J'!B23 -> 0:0 | Y8: ='Paweł J'!B24 -> 1:1 | Z8: ='Paweł J'!B25 -> 0:1 | AA8: ='Paweł J'!B26 -> 0:0 | AB8: ='Paweł J'!B27 -> 1:0 | AC8: ='Paweł J'!B28 -> 2:0 | AD8: ='Paweł J'!B29 -> 1:0 | AE8: ='Paweł J'!B30 -> 1:1 | AF8: ='Paweł J'!B31 -> 0:2 | AG8: ='Paweł J'!B32 -> 7:0 | AH8: ='Paweł J'!B33 -> 0:0 | AI8: ='Paweł J'!B34 -> 0:0 | AJ8: ='Paweł J'!B35 -> 2:0 | AK8: ='Paweł J'!B36 -> 4:0 | AL8: ='Paweł J'!B37 -> 1:2 | AM8: ='Paweł J'!B38 -> 3:0 | AN8: ='Paweł J'!B39 -> 2:0 | AO8: ='Paweł J'!B40 -> 3:0 | AP8: ='Paweł J'!B41 -> 0:2 | AQ8: ='Paweł J'!B42 -> 2:0 | AR8: ='Paweł J'!B43 -> 3:0 | AS8: ='Paweł J'!B44 -> 1:0 | AT8: ='Paweł J'!B45 -> 0:1 | AU8: ='Paweł J'!B46 -> 1:0 | AV8: ='Paweł J'!B47 -> 0:1 | AW8: ='Paweł J'!B48 -> 0:2 | AX8: ='Paweł J'!B49 -> 1:0 | AY8: ='Paweł J'!B50 -> 0:0 | AZ8: ='Paweł J'!B51 -> 0:0 | BA8: ='Paweł J'!B52 -> 0:3 | BB8: ='Paweł J'!B53 -> 3:0 | BC8: ='Paweł J'!B54 -> 0:1 | BD8: ='Paweł J'!B55 -> 2:1 | BE8: ='Paweł J'!B56 -> 1:3 | BF8: ='Paweł J'!B57 -> 0:2 | BG8: ='Paweł J'!B58 -> 0:1 | BH8: ='Paweł J'!B59 -> 1:1 | BI8: ='Paweł J'!B60 -> 2:0 | BJ8: ='Paweł J'!B61 -> 1:0 | BK8: ='Paweł J'!B62 -> 1:1 | BL8: ='Paweł J'!B63 -> 2:0 | BM8: ='Paweł J'!B64 -> 2:2 | BN8: ='Paweł J'!B65 -> 1:1 | BO8: ='Paweł J'!B66 -> 1:0 | BP8: ='Paweł J'!B67 -> 0:4 | BQ8: ='Paweł J'!B68 -> 0:3 | BR8: ='Paweł J'!B69 -> 2:0 | BS8: ='Paweł J'!B70 -> 1:1 | BT8: ='Paweł J'!B71 -> 0:1 | BU8: ='Paweł J'!B72 -> 0:0 | BV8: ='Paweł J'!B73 -> 0:3 | BW8: ='Paweł J'!D74 -> 3
A9: Paweł P | B9: =BW9 -> 3 | C9: ='Paweł P'!B2 -> 2:0 | D9: ='Paweł P'!B3 -> 1:1 | E9: ='Paweł P'!B4 -> 2:2 | F9: ='Paweł P'!B5 -> 3:1 | G9: ='Paweł P'!B6 -> 0:3 | H9: ='Paweł P'!B7 -> 2:1 | I9: ='Paweł P'!B8 -> 0:0 | J9: ='Paweł P'!B9 -> 1:3 | K9: ='Paweł P'!B10 -> 2:0 | L9: ='Paweł P'!B11 -> 1:0 | M9: ='Paweł P'!B12 -> 0:0 | N9: ='Paweł P'!B13 -> 0:1 | O9: ='Paweł P'!B14 -> 4:0 | P9: ='Paweł P'!B15 -> 3:1 | Q9: ='Paweł P'!B16 -> 0:2 | R9: ='Paweł P'!B17 -> 2:0 | S9: ='Paweł P'!B18 -> 0:1 | T9: ='Paweł P'!B19 -> 0:3 | U9: ='Paweł P'!B20 -> 3:2 | V9: ='Paweł P'!B21 -> 2:1 | W9: ='Paweł P'!B22 -> 3:0 | X9: ='Paweł P'!B23 -> 0:0 | Y9: ='Paweł P'!B24 -> 2:1 | Z9: ='Paweł P'!B25 -> 1:3 | AA9: ='Paweł P'!B26 -> 1:0 | AB9: ='Paweł P'!B27 -> 1:0 | AC9: ='Paweł P'!B28 -> 2:0 | AD9: ='Paweł P'!B29 -> 1:0 | AE9: ='Paweł P'!B30 -> 2:0 | AF9: ='Paweł P'!B31 -> 0:2 | AG9: ='Paweł P'!B32 -> 5:0 | AH9: ='Paweł P'!B33 -> 2:2 | AI9: ='Paweł P'!B34 -> 3:0 | AJ9: ='Paweł P'!B35 -> 3:2 | AK9: ='Paweł P'!B36 -> 0:1 | AL9: ='Paweł P'!B37 -> 0:2 | AM9: ='Paweł P'!B38 -> 2:0 | AN9: ='Paweł P'!B39 -> 0:0 | AO9: ='Paweł P'!B40 -> 3:0 | AP9: ='Paweł P'!B41 -> 0:0 | AQ9: ='Paweł P'!B42 -> 1:0 | AR9: ='Paweł P'!B43 -> 4:1 | AS9: ='Paweł P'!B44 -> 3:0 | AT9: ='Paweł P'!B45 -> 3:3 | AU9: ='Paweł P'!B46 -> 2:1 | AV9: ='Paweł P'!B47 -> 2:2 | AW9: ='Paweł P'!B48 -> 0:1 | AX9: ='Paweł P'!B49 -> 1:1 | AY9: ='Paweł P'!B50 -> 1:1 | AZ9: ='Paweł P'!B51 -> 0:0 | BA9: ='Paweł P'!B52 -> 1:3 | BB9: ='Paweł P'!B53 -> 2:0 | BC9: ='Paweł P'!B54 -> 0:2 | BD9: ='Paweł P'!B55 -> 1:1 | BE9: ='Paweł P'!B56 -> 0:0 | BF9: ='Paweł P'!B57 -> 1:4 | BG9: ='Paweł P'!B58 -> 0:0 | BH9: ='Paweł P'!B59 -> 0:2 | BI9: ='Paweł P'!B60 -> 2:2 | BJ9: ='Paweł P'!B61 -> 2:1 | BK9: ='Paweł P'!B62 -> 2:2 | BL9: ='Paweł P'!B63 -> 3:0 | BM9: ='Paweł P'!B64 -> 0:2 | BN9: ='Paweł P'!B65 -> 0:2 | BO9: ='Paweł P'!B66 -> 0:0 | BP9: ='Paweł P'!B67 -> 1:3 | BQ9: ='Paweł P'!B68 -> 1:3 | BR9: ='Paweł P'!B69 -> 1:0 | BS9: ='Paweł P'!B70 -> 0:2 | BT9: ='Paweł P'!B71 -> 0:0 | BU9: ='Paweł P'!B72 -> 0:3 | BV9: ='Paweł P'!B73 -> 0:3 | BW9: ='Paweł P'!D74 -> 3
A10: Paulina | B10: =BW10 -> 3 | C10: =Paulina!B2 -> 2:0 | D10: =Paulina!B3 -> 1:1 | E10: =Paulina!B4 -> 2:1 | F10: =Paulina!B5 -> 0:2 | G10: =Paulina!B6 -> 0:2 | H10: =Paulina!B7 -> 2:1 | I10: =Paulina!B8 -> 0:2 | J10: =Paulina!B9 -> 1:2 | K10: =Paulina!B10 -> 3:0 | L10: =Paulina!B11 -> 2:1 | M10: =Paulina!B12 -> 1:1 | N10: =Paulina!B13 -> 1:0 | O10: =Paulina!B14 -> 3:0 | P10: =Paulina!B15 -> 2:0 | Q10: =Paulina!B16 -> 0:2 | R10: =Paulina!B17 -> 2:1 | S10: =Paulina!B18 -> 2:0 | T10: =Paulina!B19 -> 0:2 | U10: =Paulina!B20 -> 3:0 | V10: =Paulina!B21 -> 2:0 | W10: =Paulina!B22 -> 3:0 | X10: =Paulina!B23 -> 2:1 | Y10: =Paulina!B24 -> 1:1 | Z10: =Paulina!B25 -> 1:0 | AA10: =Paulina!B26 -> 1:0 | AB10: =Paulina!B27 -> 2:0 | AC10: =Paulina!B28 -> 2:1 | AD10: =Paulina!B29 -> 1:1 | AE10: =Paulina!B30 -> 1:0 | AF10: =Paulina!B31 -> 1:2 | AG10: =Paulina!B32 -> 3:0 | AH10: =Paulina!B33 -> 1:1 | AI10: =Paulina!B34 -> 2:1 | AJ10: =Paulina!B35 -> 2:0 | AK10: =Paulina!B36 -> 2:0 | AL10: =Paulina!B37 -> 0:1 | AM10: =Paulina!B38 -> 3:0 | AN10: =Paulina!B39 -> 2:0 | AO10: =Paulina!B40 -> 2:0 | AP10: =Paulina!B41 -> 0:1 | AQ10: =Paulina!B42 -> 2:0 | AR10: =Paulina!B43 -> 3:0 | AS10: =Paulina!B44 -> 2:1 | AT10: =Paulina!B45 -> 0:2 | AU10: =Paulina!B46 -> 3:0 | AV10: =Paulina!B47 -> 3:0 | AW10: =Paulina!B48 -> 0:3 | AX10: =Paulina!B49 -> 2:0 | AY10: =Paulina!B50 -> 1:1 | AZ10: =Paulina!B51 -> 0:1 | BA10: =Paulina!B52 -> 0:3 | BB10: =Paulina!B53 -> 2:0 | BC10: =Paulina!B54 -> 1:1 | BD10: =Paulina!B55 -> 0:1 | BE10: =Paulina!B56 -> 0:2 | BF10: =Paulina!B57 -> 0:3 | BG10: =Paulina!B58 -> 1:1 | BH10: =Paulina!B59 -> 0:2 | BI10: =Paulina!B60 -> 1:1 | BJ10: =Paulina!B61 -> 1:2 | BK10: =Paulina!B62 -> 3:2 | BL10: =Paulina!B63 -> 2:0 | BM10: =Paulina!B64 -> 1:1 | BN10: =Paulina!B65 -> 0:2 | BO10: =Paulina!B66 -> 1:1 | BP10: =Paulina!B67 -> 0:2 | BQ10: =Paulina!B68 -> 0:3 | BR10: =Paulina!B69 -> 2:0 | BS10: =Paulina!B70 -> 1:2 | BT10: =Paulina!B71 -> 1:1 | BU10: =Paulina!B72 -> 1:2 | BV10: =Paulina!B73 -> 0:3 | BW10: =Paulina!D74 -> 3
A11: Maja | B11: =BW11 -> 2 | C11: =Maja!B2 -> 3:0 | D11: =Maja!B3 -> 3:2 | E11: =Maja!B4 -> 1:0 | F11: =Maja!B5 -> 3:3 | G11: =Maja!B6 -> 5:2 | H11: =Maja!B7 -> 4:1 | I11: =Maja!B8 -> 5:4 | J11: =Maja!B9 -> 1:5 | K11: =Maja!B10 -> 6:2 | L11: =Maja!B11 -> 3:2 | M11: =Maja!B12 -> 5:6 | N11: =Maja!B13 -> 1:4 | O11: =Maja!B14 -> 4:5 | P11: =Maja!B15 -> 3:2 | Q11: =Maja!B16 -> 2:4 | R11: =Maja!B17 -> 2:5 | S11: =Maja!B18 -> 3:3 | T11: =Maja!B19 -> 3:1 | U11: =Maja!B20 -> 3:0 | V11: =Maja!B21 -> 3:4 | W11: =Maja!B22 -> 3:2 | X11: =Maja!B23 -> 2:4 | Y11: =Maja!B24 -> 3:2 | Z11: =Maja!B25 -> 1:5 | AA11: =Maja!B26 -> 3:2 | AB11: =Maja!B27 -> 3:5 | AC11: =Maja!B28 -> 4:2 | AD11: =Maja!B29 -> 3:4 | AE11: =Maja!B30 -> 1:4 | AF11: =Maja!B31 -> 4:3 | AG11: =Maja!B32 -> 2:0 | AH11: =Maja!B33 -> 3:3 | AI11: =Maja!B34 -> 3:2 | AJ11: =Maja!B35 -> 4:1 | AK11: =Maja!B36 -> 1:2 | AL11: =Maja!B37 -> 2:3 | AM11: =Maja!B38 -> 3:2 | AN11: =Maja!B39 -> 2:0 | AO11: =Maja!B40 -> 3:1 | AP11: =Maja!B41 -> 3:1 | AQ11: =Maja!B42 -> 3:2 | AR11: =Maja!B43 -> 3:2 | AS11: =Maja!B44 -> 3:3 | AT11: =Maja!B45 -> 4:2 | AU11: =Maja!B46 -> 4:1 | AV11: =Maja!B47 -> 3:0 | AW11: =Maja!B48 -> 1:5 | AX11: =Maja!B49 -> 3:0 | AY11: =Maja!B50 -> 0:3 | AZ11: =Maja!B51 -> 3:3 | BA11: =Maja!B52 -> 1:3 | BB11: =Maja!B53 -> 3:0 | BC11: =Maja!B54 -> 3:2 | BD11: =Maja!B55 -> 3:2 | BE11: =Maja!B56 -> 3:0 | BF11: =Maja!B57 -> 2:2 | BG11: =Maja!B58 -> 3:4 | BH11: =Maja!B59 -> 3:4 | BI11: =Maja!B60 -> 1:1 | BJ11: =Maja!B61 -> 0:2 | BK11: =Maja!B62 -> 1:3 | BL11: =Maja!B63 -> 3:1 | BM11: =Maja!B64 -> 3:0 | BN11: =Maja!B65 -> 1:3 | BO11: =Maja!B66 -> 2:2 | BP11: =Maja!B67 -> 3:1 | BQ11: =Maja!B68 -> 3:2 | BR11: =Maja!B69 -> 3:1 | BS11: =Maja!B70 -> 3:2 | BT11: =Maja!B71 -> 0:1 | BU11: =Maja!B72 -> 3:0 | BV11: =Maja!B73 -> 0:3 | BW11: =Maja!D74 -> 2
A12: Karolek Asi | B12: =BW12 -> 1 | C12: ='Karolek Asi'!B2 -> 2:1 | D12: ='Karolek Asi'!B3 -> 1:1 | E12: ='Karolek Asi'!B4 -> 0:2 | F12: ='Karolek Asi'!B5 -> 1:1 | G12: ='Karolek Asi'!B6 -> 0:2 | H12: ='Karolek Asi'!B7 -> 2:0 | I12: ='Karolek Asi'!B8 -> 0:2 | J12: ='Karolek Asi'!B9 -> 0:2 | K12: ='Karolek Asi'!B10 -> 4:0 | L12: ='Karolek Asi'!B11 -> 1:1 | M12: ='Karolek Asi'!B12 -> 2:2 | N12: ='Karolek Asi'!B13 -> 1:0 | O12: ='Karolek Asi'!B14 -> 3:0 | P12: ='Karolek Asi'!B15 -> 2:1 | Q12: ='Karolek Asi'!B16 -> 0:2 | R12: ='Karolek Asi'!B17 -> 2:0 | S12: ='Karolek Asi'!B18 -> 2:0 | T12: ='Karolek Asi'!B19 -> 0:2 | U12: ='Karolek Asi'!B20 -> 2:0 | V12: ='Karolek Asi'!B21 -> 2:1 | W12: ='Karolek Asi'!B22 -> 4:0 | X12: ='Karolek Asi'!B23 -> 1:1 | Y12: ='Karolek Asi'!B24 -> 1:0 | Z12: ='Karolek Asi'!B25 -> 1:1 | AA12: ='Karolek Asi'!B26 -> 1:0 | AB12: ='Karolek Asi'!B27 -> 0:1 | AC12: ='Karolek Asi'!B28 -> 2:0 | AD12: ='Karolek Asi'!B29 -> 2:1 | AE12: ='Karolek Asi'!B30 -> 2:1 | AF12: ='Karolek Asi'!B31 -> 0:1 | AG12: ='Karolek Asi'!B32 -> 3:0 | AH12: ='Karolek Asi'!B33 -> 2:2 | AI12: ='Karolek Asi'!B34 -> 3:1 | AJ12: ='Karolek Asi'!B35 -> 2:1 | AK12: ='Karolek Asi'!B36 -> 2:0 | AL12: ='Karolek Asi'!B37 -> 0:2 | AM12: ='Karolek Asi'!B38 -> 2:0 | AN12: ='Karolek Asi'!B39 -> 1:0 | AO12: ='Karolek Asi'!B40 -> 2:0 | AP12: ='Karolek Asi'!B41 -> 0:1 | AQ12: ='Karolek Asi'!B42 -> 1:0 | AR12: ='Karolek Asi'!B43 -> 3:0 | AS12: ='Karolek Asi'!B44 -> 0:1 | AT12: ='Karolek Asi'!B45 -> 0:1 | AU12: ='Karolek Asi'!B46 -> 2:0 | AV12: ='Karolek Asi'!B47 -> 2:0 | AW12: ='Karolek Asi'!B48 -> 0:2 | AX12: ='Karolek Asi'!B49 -> 2:0 | AY12: ='Karolek Asi'!B50 -> 2:2 | AZ12: ='Karolek Asi'!B51 -> 2:0 | BA12: ='Karolek Asi'!B52 -> 1:3 | BB12: ='Karolek Asi'!B53 -> 1:0 | BC12: ='Karolek Asi'!B54 -> 1:1 | BD12: ='Karolek Asi'!B55 -> 0:0 | BE12: ='Karolek Asi'!B56 -> 0:2 | BF12: ='Karolek Asi'!B57 -> 0:1 | BG12: ='Karolek Asi'!B58 -> 2:1 | BH12: ='Karolek Asi'!B59 -> 0:2 | BI12: ='Karolek Asi'!B60 -> 1:1 | BJ12: ='Karolek Asi'!B61 -> 1:0 | BK12: ='Karolek Asi'!B62 -> 1:3 | BL12: ='Karolek Asi'!B63 -> 2:0 | BM12: ='Karolek Asi'!B64 -> 1:1 | BN12: ='Karolek Asi'!B65 -> 1:2 | BO12: ='Karolek Asi'!B66 -> 1:0 | BP12: ='Karolek Asi'!B67 -> 0:2 | BQ12: ='Karolek Asi'!B68 -> 0:2 | BR12: ='Karolek Asi'!B69 -> 1:0 | BS12: ='Karolek Asi'!B70 -> 1:1 | BT12: ='Karolek Asi'!B71 -> 0:1 | BU12: ='Karolek Asi'!B72 -> 0:0 | BV12: ='Karolek Asi'!B73 -> 0:3 | BW12: ='Karolek Asi'!D74 -> 1
A13: Janusz Soko | B13: =BW13 -> 1 | C13: ='Janusz Soko'!B2 -> 3:2 | D13: ='Janusz Soko'!B3 -> 2:2 | E13: ='Janusz Soko'!B4 -> 0:1 | F13: ='Janusz Soko'!B5 -> 1:2 | G13: ='Janusz Soko'!B6 -> 3:1 | H13: ='Janusz Soko'!B7 -> 3:2 | I13: ='Janusz Soko'!B8 -> 2:2 | J13: ='Janusz Soko'!B9 -> 0:1 | K13: ='Janusz Soko'!B10 -> 1:2 | L13: ='Janusz Soko'!B11 -> 3:1 | M13: ='Janusz Soko'!B12 -> 3:2 | N13: ='Janusz Soko'!B13 -> 2:2 | O13: ='Janusz Soko'!B14 -> 0:1 | P13: ='Janusz Soko'!B15 -> 1:2 | Q13: ='Janusz Soko'!B16 -> 3:1 | R13: ='Janusz Soko'!B17 -> 3:2 | S13: ='Janusz Soko'!B18 -> 2:2 | T13: ='Janusz Soko'!B19 -> 0:1 | U13: ='Janusz Soko'!B20 -> 1:2 | V13: ='Janusz Soko'!B21 -> 3:1 | W13: ='Janusz Soko'!B22 -> 3:2 | X13: ='Janusz Soko'!B23 -> 2:2 | Y13: ='Janusz Soko'!B24 -> 0:1 | Z13: ='Janusz Soko'!B25 -> 1:2 | AA13: ='Janusz Soko'!B26 -> 3:1 | AB13: ='Janusz Soko'!B27 -> 3:2 | AC13: ='Janusz Soko'!B28 -> 2:2 | AD13: ='Janusz Soko'!B29 -> 0:1 | AE13: ='Janusz Soko'!B30 -> 1:2 | AF13: ='Janusz Soko'!B31 -> 3:1 | AG13: ='Janusz Soko'!B32 -> 3:2 | AH13: ='Janusz Soko'!B33 -> 2:2 | AI13: ='Janusz Soko'!B34 -> 0:1 | AJ13: ='Janusz Soko'!B35 -> 1:2 | AK13: ='Janusz Soko'!B36 -> 3:1 | AL13: ='Janusz Soko'!B37 -> 3:2 | AM13: ='Janusz Soko'!B38 -> 2:2 | AN13: ='Janusz Soko'!B39 -> 0:1 | AO13: ='Janusz Soko'!B40 -> 1:2 | AP13: ='Janusz Soko'!B41 -> 3:1 | AQ13: ='Janusz Soko'!B42 -> 3:2 | AR13: ='Janusz Soko'!B43 -> 2:2 | AS13: ='Janusz Soko'!B44 -> 0:1 | AT13: ='Janusz Soko'!B45 -> 1:2 | AU13: ='Janusz Soko'!B46 -> 3:1 | AV13: ='Janusz Soko'!B47 -> 3:2 | AW13: ='Janusz Soko'!B48 -> 2:2 | AX13: ='Janusz Soko'!B49 -> 0:1 | AY13: ='Janusz Soko'!B50 -> 1:2 | AZ13: ='Janusz Soko'!B51 -> 3:1 | BA13: ='Janusz Soko'!B52 -> 3:2 | BB13: ='Janusz Soko'!B53 -> 2:2 | BC13: ='Janusz Soko'!B54 -> 0:1 | BD13: ='Janusz Soko'!B55 -> 1:2 | BE13: ='Janusz Soko'!B56 -> 3:1 | BF13: ='Janusz Soko'!B57 -> 3:2 | BG13: ='Janusz Soko'!B58 -> 2:2 | BH13: ='Janusz Soko'!B59 -> 0:1 | BI13: ='Janusz Soko'!B60 -> 1:2 | BJ13: ='Janusz Soko'!B61 -> 3:1 | BK13: ='Janusz Soko'!B62 -> 3:2 | BL13: ='Janusz Soko'!B63 -> 2:2 | BM13: ='Janusz Soko'!B64 -> 0:1 | BN13: ='Janusz Soko'!B65 -> 1:2 | BO13: ='Janusz Soko'!B66 -> 3:1 | BP13: ='Janusz Soko'!B67 -> 3:2 | BQ13: ='Janusz Soko'!B68 -> 2:2 | BR13: ='Janusz Soko'!B69 -> 0:1 | BS13: ='Janusz Soko'!B70 -> 1:2 | BT13: ='Janusz Soko'!B71 -> 3:1 | BU13: ='Janusz Soko'!B72 -> 3:2 | BV13: ='Janusz Soko'!B73 -> 2:2 | BW13: ='Janusz Soko'!D74 -> 1
A14: Michał Klaudii | B14: =BW14 -> 1 | C14: ='Michał Klaudii'!B2 -> 3:1 | D14: ='Michał Klaudii'!B3 -> 1:2 | E14: ='Michał Klaudii'!B4 -> 2:1 | F14: ='Michał Klaudii'!B5 -> 2:0 | G14: ='Michał Klaudii'!B6 -> 0:2 | H14: ='Michał Klaudii'!B7 -> 2:1 | I14: ='Michał Klaudii'!B8 -> 0:2 | J14: ='Michał Klaudii'!B9 -> 1:1 | K14: ='Michał Klaudii'!B10 -> 4:0 | L14: ='Michał Klaudii'!B11 -> 2:1 | M14: ='Michał Klaudii'!B12 -> 1:1 | N14: ='Michał Klaudii'!B13 -> 2:0 | O14: ='Michał Klaudii'!B14 -> 6:0 | P14: ='Michał Klaudii'!B15 -> 2:1 | Q14: ='Michał Klaudii'!B16 -> 0:2 | R14: ='Michał Klaudii'!B17 -> 1:1 | S14: ='Michał Klaudii'!B18 -> 2:0 | T14: ='Michał Klaudii'!B19 -> 1:2 | U14: ='Michał Klaudii'!B20 -> 3:0 | V14: ='Michał Klaudii'!B21 -> 2:0 | W14: ='Michał Klaudii'!B22 -> 3:0 | X14: ='Michał Klaudii'!B23 -> 2:1 | Y14: ='Michał Klaudii'!B24 -> 2:0 | Z14: ='Michał Klaudii'!B25 -> 1:2 | AA14: ='Michał Klaudii'!B26 -> 2:0 | AB14: ='Michał Klaudii'!B27 -> 2:1 | AC14: ='Michał Klaudii'!B28 -> 2:1 | AD14: ='Michał Klaudii'!B29 -> 2:0 | AE14: ='Michał Klaudii'!B30 -> 2:1 | AF14: ='Michał Klaudii'!B31 -> 1:1 | AG14: ='Michał Klaudii'!B32 -> 4:0 | AH14: ='Michał Klaudii'!B33 -> 2:1 | AI14: ='Michał Klaudii'!B34 -> 2:1 | AJ14: ='Michał Klaudii'!B35 -> 3:1 | AK14: ='Michał Klaudii'!B36 -> 4:0 | AL14: ='Michał Klaudii'!B37 -> 1:2 | AM14: ='Michał Klaudii'!B38 -> 4:0 | AN14: ='Michał Klaudii'!B39 -> 2:0 | AO14: ='Michał Klaudii'!B40 -> 3:0 | AP14: ='Michał Klaudii'!B41 -> 1:2 | AQ14: ='Michał Klaudii'!B42 -> 2:0 | AR14: ='Michał Klaudii'!B43 -> 3:0 | AS14: ='Michał Klaudii'!B44 -> 1:1 | AT14: ='Michał Klaudii'!B45 -> 0:2 | AU14: ='Michał Klaudii'!B46 -> 3:1 | AV14: ='Michał Klaudii'!B47 -> 2:1 | AW14: ='Michał Klaudii'!B48 -> 0:3 | AX14: ='Michał Klaudii'!B49 -> 3:0 | AY14: ='Michał Klaudii'!B50 -> 2:1 | AZ14: ='Michał Klaudii'!B51 -> 2:0 | BA14: ='Michał Klaudii'!B52 -> 0:2 | BB14: ='Michał Klaudii'!B53 -> 3:0 | BC14: ='Michał Klaudii'!B54 -> 1:2 | BD14: ='Michał Klaudii'!B55 -> 1:1 | BE14: ='Michał Klaudii'!B56 -> 0:3 | BF14: ='Michał Klaudii'!B57 -> 1:3 | BG14: ='Michał Klaudii'!B58 -> 1:1 | BH14: ='Michał Klaudii'!B59 -> 0:2 | BI14: ='Michał Klaudii'!B60 -> 1:1 | BJ14: ='Michał Klaudii'!B61 -> 2:1 | BK14: ='Michał Klaudii'!B62 -> 0:2 | BL14: ='Michał Klaudii'!B63 -> 2:0 | BM14: ='Michał Klaudii'!B64 -> 1:1 | BN14: ='Michał Klaudii'!B65 -> 1:2 | BO14: ='Michał Klaudii'!B66 -> 1:1 | BP14: ='Michał Klaudii'!B67 -> 0:3 | BQ14: ='Michał Klaudii'!B68 -> 0:3 | BR14: ='Michał Klaudii'!B69 -> 2:1 | BS14: ='Michał Klaudii'!B70 -> 1:2 | BT14: ='Michał Klaudii'!B71 -> 1:1 | BU14: ='Michał Klaudii'!B72 -> 1:1 | BV14: ='Michał Klaudii'!B73 -> 0:4 | BW14: ='Michał Klaudii'!D74 -> 1
A15: Monika Soko | B15: =BW15 -> 1 | C15: ='Monika Soko'!B2 -> 2:1 | D15: ='Monika Soko'!B3 -> 1:1 | E15: ='Monika Soko'!B4 -> 2:0 | F15: ='Monika Soko'!B5 -> 3:1 | G15: ='Monika Soko'!B6 -> 1:0 | H15: ='Monika Soko'!B7 -> 2:1 | I15: ='Monika Soko'!B8 -> 1:1 | J15: ='Monika Soko'!B9 -> 2:0 | K15: ='Monika Soko'!B10 -> 3:1 | L15: ='Monika Soko'!B11 -> 1:0 | M15: ='Monika Soko'!B12 -> 2:1 | N15: ='Monika Soko'!B13 -> 1:1 | O15: ='Monika Soko'!B14 -> 2:0 | P15: ='Monika Soko'!B15 -> 3:1 | Q15: ='Monika Soko'!B16 -> 1:0 | R15: ='Monika Soko'!B17 -> 2:1 | S15: ='Monika Soko'!B18 -> 1:1 | T15: ='Monika Soko'!B19 -> 2:0 | U15: ='Monika Soko'!B20 -> 3:1 | V15: ='Monika Soko'!B21 -> 1:0 | W15: ='Monika Soko'!B22 -> 2:1 | X15: ='Monika Soko'!B23 -> 1:1 | Y15: ='Monika Soko'!B24 -> 2:0 | Z15: ='Monika Soko'!B25 -> 3:1 | AA15: ='Monika Soko'!B26 -> 1:0 | AB15: ='Monika Soko'!B27 -> 2:1 | AC15: ='Monika Soko'!B28 -> 1:1 | AD15: ='Monika Soko'!B29 -> 2:0 | AE15: ='Monika Soko'!B30 -> 3:1 | AF15: ='Monika Soko'!B31 -> 1:0 | AG15: ='Monika Soko'!B32 -> 2:1 | AH15: ='Monika Soko'!B33 -> 1:1 | AI15: ='Monika Soko'!B34 -> 2:0 | AJ15: ='Monika Soko'!B35 -> 3:1 | AK15: ='Monika Soko'!B36 -> 1:0 | AL15: ='Monika Soko'!B37 -> 2:1 | AM15: ='Monika Soko'!B38 -> 1:1 | AN15: ='Monika Soko'!B39 -> 2:0 | AO15: ='Monika Soko'!B40 -> 3:1 | AP15: ='Monika Soko'!B41 -> 1:0 | AQ15: ='Monika Soko'!B42 -> 2:1 | AR15: ='Monika Soko'!B43 -> 1:1 | AS15: ='Monika Soko'!B44 -> 2:0 | AT15: ='Monika Soko'!B45 -> 3:1 | AU15: ='Monika Soko'!B46 -> 1:0 | AV15: ='Monika Soko'!B47 -> 2:1 | AW15: ='Monika Soko'!B48 -> 1:1 | AX15: ='Monika Soko'!B49 -> 2:0 | AY15: ='Monika Soko'!B50 -> 3:1 | AZ15: ='Monika Soko'!B51 -> 1:0 | BA15: ='Monika Soko'!B52 -> 2:1 | BB15: ='Monika Soko'!B53 -> 1:1 | BC15: ='Monika Soko'!B54 -> 2:0 | BD15: ='Monika Soko'!B55 -> 3:1 | BE15: ='Monika Soko'!B56 -> 1:0 | BF15: ='Monika Soko'!B57 -> 2:1 | BG15: ='Monika Soko'!B58 -> 1:1 | BH15: ='Monika Soko'!B59 -> 2:0 | BI15: ='Monika Soko'!B60 -> 3:1 | BJ15: ='Monika Soko'!B61 -> 1:0 | BK15: ='Monika Soko'!B62 -> 2:1 | BL15: ='Monika Soko'!B63 -> 1:1 | BM15: ='Monika Soko'!B64 -> 2:0 | BN15: ='Monika Soko'!B65 -> 3:1 | BO15: ='Monika Soko'!B66 -> 1:0 | BP15: ='Monika Soko'!B67 -> 2:1 | BQ15: ='Monika Soko'!B68 -> 1:1 | BR15: ='Monika Soko'!B69 -> 2:0 | BS15: ='Monika Soko'!B70 -> 3:1 | BT15: ='Monika Soko'!B71 -> 1:0 | BU15: ='Monika Soko'!B72 -> 2:1 | BV15: ='Monika Soko'!B73 -> 1:1 | BW15: ='Monika Soko'!D74 -> 1
A16: Adam | B16: =BW16 -> 1 | C16: =Adam!B2 -> 3:0 | D16: =Adam!B3 -> 0:1 | E16: =Adam!B4 -> 2:1 | F16: =Adam!B5 -> 3:2 | G16: =Adam!B6 -> 0:1 | H16: =Adam!B7 -> 3:1 | I16: =Adam!B8 -> 2:1 | J16: =Adam!B9 -> 2:1 | K16: =Adam!B10 -> 2:0 | L16: =Adam!B11 -> 3:1 | M16: =Adam!B12 -> 2:2 | N16: =Adam!B13 -> 1:2 | O16: =Adam!B14 -> 4:0 | P16: =Adam!B15 -> 2:0 | Q16: =Adam!B16 -> 1:3 | R16: =Adam!B17 -> 1:3 | S16: =Adam!B18 -> 2:2 | T16: =Adam!B19 -> 1:0 | U16: =Adam!B20 -> 2:0 | V16: =Adam!B21 -> 2:1 | W16: =Adam!B22 -> 3:0 | X16: =Adam!B23 -> 3:1 | Y16: =Adam!B24 -> 2:0 | Z16: =Adam!B25 -> 0:1 | AA16: =Adam!B26 -> 0:1 | AB16: =Adam!B27 -> 2:0 | AC16: =Adam!B28 -> 1:0 | AD16: =Adam!B29 -> 2:0 | AE16: =Adam!B30 -> 1:1 | AF16: =Adam!B31 -> 0:0 | AG16: =Adam!B32 -> 3:1 | AH16: =Adam!B33 -> 1:1 | AI16: =Adam!B34 -> 2:1 | AJ16: =Adam!B35 -> 3:0 | AK16: =Adam!B36 -> 2:1 | AL16: =Adam!B37 -> 0:2 | AM16: =Adam!B38 -> 3:1 | AN16: =Adam!B39 -> 1:0 | AO16: =Adam!B40 -> 3:0 | AP16: =Adam!B41 -> 1:2 | AQ16: =Adam!B42 -> 2:0 | AR16: =Adam!B43 -> 3:0 | AS16: =Adam!B44 -> 1:2 | AT16: =Adam!B45 -> 1:2 | AU16: =Adam!B46 -> 4:0 | AV16: =Adam!B47 -> 2:0 | AW16: =Adam!B48 -> 0:2 | AX16: =Adam!B49 -> 3:0 | AY16: =Adam!B50 -> 1:1 | AZ16: =Adam!B51 -> 0:0 | BA16: =Adam!B52 -> 0:2 | BB16: =Adam!B53 -> 3:1 | BC16: =Adam!B54 -> 1:0 | BD16: =Adam!B55 -> 2:2 | BE16: =Adam!B56 -> 0:3 | BF16: =Adam!B57 -> 1:3 | BG16: =Adam!B58 -> 2:2 | BH16: =Adam!B59 -> 1:2 | BI16: =Adam!B60 -> 1:0 | BJ16: =Adam!B61 -> 1:1 | BK16: =Adam!B62 -> 1:3 | BL16: =Adam!B63 -> 2:0 | BM16: =Adam!B64 -> 1:2 | BN16: =Adam!B65 -> 0:2 | BO16: =Adam!B66 -> 2:1 | BP16: =Adam!B67 -> 1:0 | BQ16: =Adam!B68 -> 0:3 | BR16: =Adam!B69 -> 1:0 | BS16: =Adam!B70 -> 1:0 | BT16: =Adam!B71 -> 0:0 | BU16: =Adam!B72 -> 0:1 | BV16: =Adam!B73 -> 0:4 | BW16: =Adam!D74 -> 1
A17: Ola L | B17: =BW17 -> 1 | C17: ='Ola L'!B2 -> 3:0 | D17: ='Ola L'!B3 -> 2:2 | E17: ='Ola L'!B4 -> 2:1 | F17: ='Ola L'!B5 -> 1:1 | G17: ='Ola L'!B6 -> 0:2 | H17: ='Ola L'!B7 -> 3:1 | I17: ='Ola L'!B8 -> 0:2 | J17: ='Ola L'!B9 -> 2:3 | K17: ='Ola L'!B10 -> 4:0 | L17: ='Ola L'!B11 -> 2:2 | M17: ='Ola L'!B12 -> 1:1 | N17: ='Ola L'!B13 -> 1:0 | O17: ='Ola L'!B14 -> 4:0 | P17: ='Ola L'!B15 -> 2:1 | Q17: ='Ola L'!B16 -> 0:2 | R17: ='Ola L'!B17 -> 1:0 | S17: ='Ola L'!B18 -> 2:2 | T17: ='Ola L'!B19 -> 1:2 | U17: ='Ola L'!B20 -> 2:0 | V17: ='Ola L'!B21 -> 2:2 | W17: ='Ola L'!B22 -> 3:0 | X17: ='Ola L'!B23 -> 2:1 | Y17: ='Ola L'!B24 -> 2:2 | Z17: ='Ola L'!B25 -> 1:3 | AA17: ='Ola L'!B26 -> 2:0 | AB17: ='Ola L'!B27 -> 3:1 | AC17: ='Ola L'!B28 -> 2:0 | AD17: ='Ola L'!B29 -> 1:1 | AE17: ='Ola L'!B30 -> 2:2 | AF17: ='Ola L'!B31 -> 3:1 | AG17: ='Ola L'!B32 -> 1:1 | AH17: ='Ola L'!B33 -> 2:2 | AI17: ='Ola L'!B34 -> 2:1 | AJ17: ='Ola L'!B35 -> 4:0 | AK17: ='Ola L'!B36 -> 4:1 | AL17: ='Ola L'!B37 -> 0:3 | AM17: ='Ola L'!B38 -> 4:2 | AN17: ='Ola L'!B39 -> 3:0 | AO17: ='Ola L'!B40 -> 2:1 | AP17: ='Ola L'!B41 -> 2:1 | AQ17: ='Ola L'!B42 -> 4:0 | AR17: ='Ola L'!B43 -> 3:0 | AS17: ='Ola L'!B44 -> 2:2 | AT17: ='Ola L'!B45 -> 0:2 | AU17: ='Ola L'!B46 -> 3:0 | AV17: ='Ola L'!B47 -> 3:1 | AW17: ='Ola L'!B48 -> 0:2 | AX17: ='Ola L'!B49 -> 1:1 | AY17: ='Ola L'!B50 -> 2:2 | AZ17: ='Ola L'!B51 -> 1:0 | BA17: ='Ola L'!B52 -> 1:3 | BB17: ='Ola L'!B53 -> 2:1 | BC17: ='Ola L'!B54 -> 1:2 | BD17: ='Ola L'!B55 -> 1:1 | BE17: ='Ola L'!B56 -> 2:1 | BF17: ='Ola L'!B57 -> 2:2 | BG17: ='Ola L'!B58 -> 2:1 | BH17: ='Ola L'!B59 -> 0:3 | BI17: ='Ola L'!B60 -> 1:3 | BJ17: ='Ola L'!B61 -> 2:0 | BK17: ='Ola L'!B62 -> 0:4 | BL17: ='Ola L'!B63 -> 2:2 | BM17: ='Ola L'!B64 -> 2:2 | BN17: ='Ola L'!B65 -> 3:1 | BO17: ='Ola L'!B66 -> 0:0 | BP17: ='Ola L'!B67 -> 1:3 | BQ17: ='Ola L'!B68 -> 0:3 | BR17: ='Ola L'!B69 -> 3:2 | BS17: ='Ola L'!B70 -> 1:1 | BT17: ='Ola L'!B71 -> 2:2 | BU17: ='Ola L'!B72 -> 1:1 | BV17: ='Ola L'!B73 -> 0:4 | BW17: ='Ola L'!D74 -> 1
A18: Ola R | B18: =BW18 -> 1 | C18: ='Ola R'!B2 -> 3:0 | D18: ='Ola R'!B3 -> 1:1 | E18: ='Ola R'!B4 -> 2:1 | F18: ='Ola R'!B5 -> 2:0 | G18: ='Ola R'!B6 -> 1:2 | H18: ='Ola R'!B7 -> 2:1 | I18: ='Ola R'!B8 -> 0:2 | J18: ='Ola R'!B9 -> 1:1 | K18: ='Ola R'!B10 -> 4:0 | L18: ='Ola R'!B11 -> 2:1 | M18: ='Ola R'!B12 -> 1:1 | N18: ='Ola R'!B13 -> 2:0 | O18: ='Ola R'!B14 -> 4:0 | P18: ='Ola R'!B15 -> 2:1 | Q18: ='Ola R'!B16 -> 0:2 | R18: ='Ola R'!B17 -> 1:0 | S18: ='Ola R'!B18 -> 2:1 | T18: ='Ola R'!B19 -> 0:2 | U18: ='Ola R'!B20 -> 3:1 | V18: ='Ola R'!B21 -> 2:0 | W18: ='Ola R'!B22 -> 3:0 | X18: ='Ola R'!B23 -> 3:1 | Y18: ='Ola R'!B24 -> 2:1 | Z18: ='Ola R'!B25 -> 1:2 | AA18: ='Ola R'!B26 -> 2:0 | AB18: ='Ola R'!B27 -> 2:1 | AC18: ='Ola R'!B28 -> 2:1 | AD18: ='Ola R'!B29 -> 2:0 | AE18: ='Ola R'!B30 -> 2:1 | AF18: ='Ola R'!B31 -> 1:1 | AG18: ='Ola R'!B32 -> 4:0 | AH18: ='Ola R'!B33 -> 1:1 | AI18: ='Ola R'!B34 -> 2:1 | AJ18: ='Ola R'!B35 -> 2:0 | AK18: ='Ola R'!B36 -> 3:0 | AL18: ='Ola R'!B37 -> 1:2 | AM18: ='Ola R'!B38 -> 3:0 | AN18: ='Ola R'!B39 -> 2:0 | AO18: ='Ola R'!B40 -> 2:0 | AP18: ='Ola R'!B41 -> 1:1 | AQ18: ='Ola R'!B42 -> 2:1 | AR18: ='Ola R'!B43 -> 3:0 | AS18: ='Ola R'!B44 -> 1:1 | AT18: ='Ola R'!B45 -> 0:2 | AU18: ='Ola R'!B46 -> 2:0 | AV18: ='Ola R'!B47 -> 2:1 | AW18: ='Ola R'!B48 -> 0:2 | AX18: ='Ola R'!B49 -> 3:0 | AY18: ='Ola R'!B50 -> 1:1 | AZ18: ='Ola R'!B51 -> 2:1 | BA18: ='Ola R'!B52 -> 0:2 | BB18: ='Ola R'!B53 -> 3:0 | BC18: ='Ola R'!B54 -> 1:2 | BD18: ='Ola R'!B55 -> 1:2 | BE18: ='Ola R'!B56 -> 0:2 | BF18: ='Ola R'!B57 -> 1:2 | BG18: ='Ola R'!B58 -> 1:1 | BH18: ='Ola R'!B59 -> 0:2 | BI18: ='Ola R'!B60 -> 1:2 | BJ18: ='Ola R'!B61 -> 1:1 | BK18: ='Ola R'!B62 -> 1:2 | BL18: ='Ola R'!B63 -> 2:0 | BM18: ='Ola R'!B64 -> 1:1 | BN18: ='Ola R'!B65 -> 0:3 | BO18: ='Ola R'!B66 -> 1:1 | BP18: ='Ola R'!B67 -> 0:2 | BQ18: ='Ola R'!B68 -> 0:3 | BR18: ='Ola R'!B69 -> 2:1 | BS18: ='Ola R'!B70 -> 1:2 | BT18: ='Ola R'!B71 -> 1:1 | BU18: ='Ola R'!B72 -> 1:2 | BV18: ='Ola R'!B73 -> 0:3 | BW18: ='Ola R'!D74 -> 1
A19: Anita | B19: =BW19 -> 1 | C19: =Anita!B2 -> 2:1 | D19: =Anita!B3 -> 1:1 | E19: =Anita!B4 -> 1:0 | F19: =Anita!B5 -> 2:1 | G19: =Anita!B6 -> 0:2 | H19: =Anita!B7 -> 2:1 | I19: =Anita!B8 -> 0:2 | J19: =Anita!B9 -> 0:1 | K19: =Anita!B10 -> 3:0 | L19: =Anita!B11 -> 2:1 | M19: =Anita!B12 -> 1:1 | N19: =Anita!B13 -> 1:0 | O19: =Anita!B14 -> 3:0 | P19: =Anita!B15 -> 2:0 | Q19: =Anita!B16 -> 0:2 | R19: =Anita!B17 -> 0:1 | S19: =Anita!B18 -> 2:0 | T19: =Anita!B19 -> 0:2 | U19: =Anita!B20 -> 2:0 | V19: =Anita!B21 -> 2:0 | W19: =Anita!B22 -> 3:0 | X19: =Anita!B23 -> 1:1 | Y19: =Anita!B24 -> 2:1 | Z19: =Anita!B25 -> 0:2 | AA19: =Anita!B26 -> 2:1 | AB19: =Anita!B27 -> 2:0 | AC19: =Anita!B28 -> 2:0 | AD19: =Anita!B29 -> 1:1 | AE19: =Anita!B30 -> 2:1 | AF19: =Anita!B31 -> 1:1 | AG19: =Anita!B32 -> 4:0 | AH19: =Anita!B33 -> 2:1 | AI19: =Anita!B34 -> 2:1 | AJ19: =Anita!B35 -> 2:0 | AK19: =Anita!B36 -> 2:0 | AL19: =Anita!B37 -> 1:1 | AM19: =Anita!B38 -> 3:0 | AN19: =Anita!B39 -> 2:0 | AO19: =Anita!B40 -> 2:0 | AP19: =Anita!B41 -> 0:1 | AQ19: =Anita!B42 -> 2:0 | AR19: =Anita!B43 -> 3:0 | AS19: =Anita!B44 -> 1:1 | AT19: =Anita!B45 -> 0:2 | AU19: =Anita!B46 -> 3:0 | AV19: =Anita!B47 -> 2:0 | AW19: =Anita!B48 -> 0:2 | AX19: =Anita!B49 -> 2:0 | AY19: =Anita!B50 -> 1:1 | AZ19: =Anita!B51 -> 1:0 | BA19: =Anita!B52 -> 0:2 | BB19: =Anita!B53 -> 3:0 | BC19: =Anita!B54 -> 1:2 | BD19: =Anita!B55 -> 1:2 | BE19: =Anita!B56 -> 0:2 | BF19: =Anita!B57 -> 1:2 | BG19: =Anita!B58 -> 1:1 | BH19: =Anita!B59 -> 0:2 | BI19: =Anita!B60 -> 1:1 | BJ19: =Anita!B61 -> 1:0 | BK19: =Anita!B62 -> 1:2 | BL19: =Anita!B63 -> 2:0 | BM19: =Anita!B64 -> 1:1 | BN19: =Anita!B65 -> 1:2 | BO19: =Anita!B66 -> 1:1 | BP19: =Anita!B67 -> 0:3 | BQ19: =Anita!B68 -> 2:0 | BR19: =Anita!B69 -> 2:1 | BS19: =Anita!B70 -> 1:2 | BT19: =Anita!B71 -> 1:1 | BU19: =Anita!B72 -> 1:1 | BV19: =Anita!B73 -> 0:3 | BW19: =Anita!D74 -> 1
A20: Agata | B20: =BW20 -> 1 | C20: =Agata!B2 -> 2-1 | D20: =Agata!B3 -> 0-1 | E20: =Agata!B4 -> 0-0 | F20: =Agata!B5 -> 0-1 | G20: =Agata!B6 -> 0-3 | H20: =Agata!B7 -> 4-1 | I20: =Agata!B8 -> 0-3 | J20: =Agata!B9 -> 1-1 | K20: =Agata!B10 -> 6-0 | L20: =Agata!B11 -> 2-1 | M20: =Agata!B12 -> 0-0 | N20: =Agata!B13 -> 3-0 | O20: =Agata!B14 -> 5-0 | P20: =Agata!B15 -> 2-0 | Q20: =Agata!B16 -> 0-2 | R20: =Agata!B17 -> 1-2 | S20: =Agata!B18 -> 4-1 | T20: =Agata!B19 -> 0-1 | U20: =Agata!B20 -> 5-1 | V20: =Agata!B21 -> 3-0 | W20: =Agata!B22 -> 1-0 | X20: =Agata!B23 -> 1-1 | Y20: =Agata!B24 -> 1-1 | Z20: =Agata!B25 -> 0-3 | AA20: =Agata!B26 -> 1-2 | AB20: =Agata!B27 -> 2-1 | AC20: =Agata!B28 -> 1-0 | AD20: =Agata!B29 -> 3-1 | AE20: =Agata!B30 -> 0-1 | AF20: =Agata!B31 -> 1-0 | AG20: =Agata!B32 -> 5-0 | AH20: =Agata!B33 -> 1-2 | AI20: =Agata!B34 -> 1-2 | AJ20: =Agata!B35 -> 4-1 | AK20: =Agata!B36 -> 3-0 | AL20: =Agata!B37 -> 1-1 | AM20: =Agata!B38 -> 3-0 | AN20: =Agata!B39 -> 2-0 | AO20: =Agata!B40 -> 3-1 | AP20: =Agata!B41 -> 1-1 | AQ20: =Agata!B42 -> 2-0 | AR20: =Agata!B43 -> 3-0 | AS20: =Agata!B44 -> 1-0 | AT20: =Agata!B45 -> 0-1 | AU20: =Agata!B46 -> 3-0 | AV20: =Agata!B47 -> 5-1 | AW20: =Agata!B48 -> 1-3 | AX20: =Agata!B49 -> 3-1 | AY20: =Agata!B50 -> 1-0 | AZ20: =Agata!B51 -> 1-0 | BA20: =Agata!B52 -> 1-2 | BB20: =Agata!B53 -> 0-1 | BC20: =Agata!B54 -> 1-2 | BD20: =Agata!B55 -> 2-0 | BE20: =Agata!B56 -> 1-1 | BF20: =Agata!B57 -> 1-3 | BG20: =Agata!B58 -> 1-2 | BH20: =Agata!B59 -> 1-3 | BI20: =Agata!B60 -> 0-0 | BJ20: =Agata!B61 -> 1-2 | BK20: =Agata!B62 -> 0-1 | BL20: =Agata!B63 -> 1-0 | BM20: =Agata!B64 -> 1-1 | BN20: =Agata!B65 -> 1-2 | BO20: =Agata!B66 -> 1-0 | BP20: =Agata!B67 -> 0-1 | BQ20: =Agata!B68 -> 1-3 | BR20: =Agata!B69 -> 3-0 | BS20: =Agata!B70 -> 1-2 | BT20: =Agata!B71 -> 1-0 | BU20: =Agata!B72 -> 1-2 | BV20: =Agata!B73 -> 0-4 | BW20: =Agata!D74 -> 1
A21: Bartosz | B21: =BW21 -> 1 | C21: =Bartosz!B2 -> 3:1 | D21: =Bartosz!B3 -> 1:3 | E21: =Bartosz!B4 -> 2:1 | F21: =Bartosz!B5 -> 0:2 | G21: =Bartosz!B6 -> 0:3 | H21: =Bartosz!B7 -> 5:0 | I21: =Bartosz!B8 -> 0:3 | J21: =Bartosz!B9 -> 0:2 | K21: =Bartosz!B10 -> 5:0 | L21: =Bartosz!B11 -> 2:0 | M21: =Bartosz!B12 -> 0:3 | N21: =Bartosz!B13 -> 3:0 | O21: =Bartosz!B14 -> 4:0 | P21: =Bartosz!B15 -> 3:0 | Q21: =Bartosz!B16 -> 0:3 | R21: =Bartosz!B17 -> 0:1 | S21: =Bartosz!B18 -> 2:1 | T21: =Bartosz!B19 -> 0:3 | U21: =Bartosz!B20 -> 3:0 | V21: =Bartosz!B21 -> 2:0 | W21: =Bartosz!B22 -> 4:0 | X21: =Bartosz!B23 -> 1:1 | Y21: =Bartosz!B24 -> 0:2 | Z21: =Bartosz!B25 -> 0:3 | AA21: =Bartosz!B26 -> 2:0 | AB21: =Bartosz!B27 -> 1:0 | AC21: =Bartosz!B28 -> 1:0 | AD21: =Bartosz!B29 -> 2:1 | AE21: =Bartosz!B30 -> 0:1 | AF21: =Bartosz!B31 -> 2:0 | AG21: =Bartosz!B32 -> 5:0 | AH21: =Bartosz!B33 -> 2:1 | AI21: =Bartosz!B34 -> 2:1 | AJ21: =Bartosz!B35 -> 4:0 | AK21: =Bartosz!B36 -> 3:0 | AL21: =Bartosz!B37 -> 0:2 | AM21: =Bartosz!B38 -> 3:0 | AN21: =Bartosz!B39 -> 2:0 | AO21: =Bartosz!B40 -> 2:0 | AP21: =Bartosz!B41 -> 2:0 | AQ21: =Bartosz!B42 -> 2:1 | AR21: =Bartosz!B43 -> 3:0 | AS21: =Bartosz!B44 -> 3:1 | AT21: =Bartosz!B45 -> 0:1 | AU21: =Bartosz!B46 -> 3:0 | AV21: =Bartosz!B47 -> 4:0 | AW21: =Bartosz!B48 -> 1:3 | AX21: =Bartosz!B49 -> 2:0 | AY21: =Bartosz!B50 -> 1:1 | AZ21: =Bartosz!B51 -> 1:0 | BA21: =Bartosz!B52 -> 0:2 | BB21: =Bartosz!B53 -> 1:0 | BC21: =Bartosz!B54 -> 1:2 | BD21: =Bartosz!B55 -> 0:2 | BE21: =Bartosz!B56 -> 0:1 | BF21: =Bartosz!B57 -> 1:2 | BG21: =Bartosz!B58 -> 0:1 | BH21: =Bartosz!B59 -> 0:2 | BI21: =Bartosz!B60 -> 2:0 | BJ21: =Bartosz!B61 -> 1:0 | BK21: =Bartosz!B62 -> 1:2 | BL21: =Bartosz!B63 -> 2:0 | BM21: =Bartosz!B64 -> 0:1 | BN21: =Bartosz!B65 -> 1:2 | BO21: =Bartosz!B66 -> 1:0 | BP21: =Bartosz!B67 -> 0:1 | BQ21: =Bartosz!B68 -> 1:3 | BR21: =Bartosz!B69 -> 2:0 | BS21: =Bartosz!B70 -> 2:3 | BT21: =Bartosz!B71 -> 0:2 | BU21: =Bartosz!B72 -> 0:2 | BV21: =Bartosz!B73 -> 0:3 | BW21: =Bartosz!D74 -> 1
A22: Ela S | B22: =BW22 -> 1 | C22: ='Ela S'!B2 -> 2-1 | D22: ='Ela S'!B3 -> 1-1 | E22: ='Ela S'!B4 -> 1-0 | F22: ='Ela S'!B5 -> 2-1 | G22: ='Ela S'!B6 -> 0-2 | H22: ='Ela S'!B7 -> 2-1 | I22: ='Ela S'!B8 -> 0-2 | J22: ='Ela S'!B9 -> 1-2 | K22: ='Ela S'!B10 -> 5-0 | L22: ='Ela S'!B11 -> 2-1 | M22: ='Ela S'!B12 -> 1-1 | N22: ='Ela S'!B13 -> 2-0 | O22: ='Ela S'!B14 -> 3-0 | P22: ='Ela S'!B15 -> 2-1 | Q22: ='Ela S'!B16 -> 0-2 | R22: ='Ela S'!B17 -> 1-0 | S22: ='Ela S'!B18 -> 3-1 | T22: ='Ela S'!B19 -> 0-3 | U22: ='Ela S'!B20 -> 2-0 | V22: ='Ela S'!B21 -> 2-0 | W22: ='Ela S'!B22 -> 4-1 | X22: ='Ela S'!B23 -> 2-1 | Y22: ='Ela S'!B24 -> 1-1 | Z22: ='Ela S'!B25 -> 0-2 | AA22: ='Ela S'!B26 -> 2-1 | AB22: ='Ela S'!B27 -> 2-1 | AC22: ='Ela S'!B28 -> 3-0 | AD22: ='Ela S'!B29 -> 1-0 | AE22: ='Ela S'!B30 -> 2-1 | AF22: ='Ela S'!B31 -> 1-2 | AG22: ='Ela S'!B32 -> 3-0 | AH22: ='Ela S'!B33 -> 2-1 | AI22: ='Ela S'!B34 -> 2-1 | AJ22: ='Ela S'!B35 -> 3-0 | AK22: ='Ela S'!B36 -> 2-0 | AL22: ='Ela S'!B37 -> 0-1 | AM22: ='Ela S'!B38 -> 3-0 | AN22: ='Ela S'!B39 -> 2-0 | AO22: ='Ela S'!B40 -> 3-0 | AP22: ='Ela S'!B41 -> 0-1 | AQ22: ='Ela S'!B42 -> 2-0 | AR22: ='Ela S'!B43 -> 3-0 | AS22: ='Ela S'!B44 -> 1-1 | AT22: ='Ela S'!B45 -> 0-2 | AU22: ='Ela S'!B46 -> 3-0 | AV22: ='Ela S'!B47 -> 3-0 | AW22: ='Ela S'!B48 -> 0-3 | AX22: ='Ela S'!B49 -> 1-1 | AY22: ='Ela S'!B50 -> 1-0 | AZ22: ='Ela S'!B51 -> 2-1 | BA22: ='Ela S'!B52 -> 0-3 | BB22: ='Ela S'!B53 -> 2-0 | BC22: ='Ela S'!B54 -> 1-1 | BD22: ='Ela S'!B55 -> 0-1 | BE22: ='Ela S'!B56 -> 0-2 | BF22: ='Ela S'!B57 -> 2-1 | BG22: ='Ela S'!B58 -> 1-1 | BH22: ='Ela S'!B59 -> 2-0 | BI22: ='Ela S'!B60 -> 2-1 | BJ22: ='Ela S'!B61 -> 1-1 | BK22: ='Ela S'!B62 -> 0-2 | BL22: ='Ela S'!B63 -> 2-0 | BM22: ='Ela S'!B64 -> 1-1 | BN22: ='Ela S'!B65 -> 1-2 | BO22: ='Ela S'!B66 -> 1-1 | BP22: ='Ela S'!B67 -> 0-3 | BQ22: ='Ela S'!B68 -> 0-3 | BR22: ='Ela S'!B69 -> 2-1 | BS22: ='Ela S'!B70 -> 1-2 | BT22: ='Ela S'!B71 -> 1-1 | BU22: ='Ela S'!B72 -> 2-1 | BV22: ='Ela S'!B73 -> 0-2 | BW22: ='Ela S'!D74 -> 1
A23: Kasia D | B23: =BW23 -> 1 | C23: ='Kasia D'!B2 -> 2:1 | D23: ='Kasia D'!B3 -> 0:2 | E23: ='Kasia D'!B4 -> 0:3 | F23: ='Kasia D'!B5 -> 2:0 | G23: ='Kasia D'!B6 -> 1:2 | H23: ='Kasia D'!B7 -> 3:1 | I23: ='Kasia D'!B8 -> 0:2 | J23: ='Kasia D'!B9 -> 0:3 | K23: ='Kasia D'!B10 -> 3:0 | L23: ='Kasia D'!B11 -> 4:3 | M23: ='Kasia D'!B12 -> 2:2 | N23: ='Kasia D'!B13 -> 2:3 | O23: ='Kasia D'!B14 -> 4:0 | P23: ='Kasia D'!B15 -> 4:0 | Q23: ='Kasia D'!B16 -> 3:1 | R23: ='Kasia D'!B17 -> 0:3 | S23: ='Kasia D'!B18 -> 3:1 | T23: ='Kasia D'!B19 -> 0:2 | U23: ='Kasia D'!B20 -> 3:0 | V23: ='Kasia D'!B21 -> 1:1 | W23: ='Kasia D'!B22 -> 4:0 | X23: ='Kasia D'!B23 -> 2:2 | Y23: ='Kasia D'!B24 -> 1:1 | Z23: ='Kasia D'!B25 -> 0:1 | AA23: ='Kasia D'!B26 -> 2:1 | AB23: ='Kasia D'!B27 -> 1:3 | AC23: ='Kasia D'!B28 -> 1:2 | AD23: ='Kasia D'!B29 -> 2:3 | AE23: ='Kasia D'!B30 -> 1:2 | AF23: ='Kasia D'!B31 -> 3:0 | AG23: ='Kasia D'!B32 -> 3:0 | AH23: ='Kasia D'!B33 -> 2:0 | AI23: ='Kasia D'!B34 -> 3:1 | AJ23: ='Kasia D'!B35 -> 4:0 | AK23: ='Kasia D'!B36 -> 2:1 | AL23: ='Kasia D'!B37 -> 0:2 | AM23: ='Kasia D'!B38 -> 3:1 | AN23: ='Kasia D'!B39 -> 2:0 | AO23: ='Kasia D'!B40 -> 2:0 | AP23: ='Kasia D'!B41 -> 0:2 | AQ23: ='Kasia D'!B42 -> 3:1 | AR23: ='Kasia D'!B43 -> 3:0 | AS23: ='Kasia D'!B44 -> 0:2 | AT23: ='Kasia D'!B45 -> 1:1 | AU23: ='Kasia D'!B46 -> 3:1 | AV23: ='Kasia D'!B47 -> 3:0 | AW23: ='Kasia D'!B48 -> 0:3 | AX23: ='Kasia D'!B49 -> 1:1 | AY23: ='Kasia D'!B50 -> 3:1 | AZ23: ='Kasia D'!B51 -> 2:2 | BA23: ='Kasia D'!B52 -> 0:2 | BB23: ='Kasia D'!B53 -> 0:0 | BC23: ='Kasia D'!B54 -> 1:2 | BD23: ='Kasia D'!B55 -> 1:1 | BE23: ='Kasia D'!B56 -> 1:1 | BF23: ='Kasia D'!B57 -> 0:4 | BG23: ='Kasia D'!B58 -> 2:2 | BH23: ='Kasia D'!B59 -> 0:2 | BI23: ='Kasia D'!B60 -> 2:0 | BJ23: ='Kasia D'!B61 -> 0:2 | BK23: ='Kasia D'!B62 -> 0:3 | BL23: ='Kasia D'!B63 -> 3:1 | BM23: ='Kasia D'!B64 -> 0:2 | BN23: ='Kasia D'!B65 -> 0:2 | BO23: ='Kasia D'!B66 -> 1:1 | BP23: ='Kasia D'!B67 -> 0:2 | BQ23: ='Kasia D'!B68 -> 0:3 | BR23: ='Kasia D'!B69 -> 3:1 | BS23: ='Kasia D'!B70 -> 1:3 | BT23: ='Kasia D'!B71 -> 0:0 | BU23: ='Kasia D'!B72 -> 1:1 | BV23: ='Kasia D'!B73 -> 0:4 | BW23: ='Kasia D'!D74 -> 1
A24: Klaudia | B24: =BW24 -> 1 | C24: =Klaudia!B2 -> 2:1 | D24: =Klaudia!B3 -> 1:1 | E24: =Klaudia!B4 -> 1:1 | F24: =Klaudia!B5 -> 2:0 | G24: =Klaudia!B6 -> 0:2 | H24: =Klaudia!B7 -> 3:1 | I24: =Klaudia!B8 -> 0:2 | J24: =Klaudia!B9 -> 1:1 | K24: =Klaudia!B10 -> 4:0 | L24: =Klaudia!B11 -> 2:1 | M24: =Klaudia!B12 -> 2:1 | N24: =Klaudia!B13 -> 2:0 | O24: =Klaudia!B14 -> 4:0 | P24: =Klaudia!B15 -> 2:0 | Q24: =Klaudia!B16 -> 0:2 | R24: =Klaudia!B17 -> 2:1 | S24: =Klaudia!B18 -> 2:1 | T24: =Klaudia!B19 -> 1:2 | U24: =Klaudia!B20 -> 3:0 | V24: =Klaudia!B21 -> 2:0 | W24: =Klaudia!B22 -> 3:0 | X24: =Klaudia!B23 -> 2:1 | Y24: =Klaudia!B24 -> 2:1 | Z24: =Klaudia!B25 -> 1:2 | AA24: =Klaudia!B26 -> 2:0 | AB24: =Klaudia!B27 -> 2:1 | AC24: =Klaudia!B28 -> 2:1 | AD24: =Klaudia!B29 -> 2:1 | AE24: =Klaudia!B30 -> 2:1 | AF24: =Klaudia!B31 -> 1:1 | AG24: =Klaudia!B32 -> 4:0 | AH24: =Klaudia!B33 -> 2:1 | AI24: =Klaudia!B34 -> 2:1 | AJ24: =Klaudia!B35 -> 3:1 | AK24: =Klaudia!B36 -> 2:0 | AL24: =Klaudia!B37 -> 1:1 | AM24: =Klaudia!B38 -> 3:0 | AN24: =Klaudia!B39 -> 2:1 | AO24: =Klaudia!B40 -> 3:0 | AP24: =Klaudia!B41 -> 0:1 | AQ24: =Klaudia!B42 -> 2:0 | AR24: =Klaudia!B43 -> 3:0 | AS24: =Klaudia!B44 -> 1:1 | AT24: =Klaudia!B45 -> 0:1 | AU24: =Klaudia!B46 -> 3:1 | AV24: =Klaudia!B47 -> 3:1 | AW24: =Klaudia!B48 -> 1:2 | AX24: =Klaudia!B49 -> 2:1 | AY24: =Klaudia!B50 -> 2:1 | AZ24: =Klaudia!B51 -> 2:0 | BA24: =Klaudia!B52 -> 0:3 | BB24: =Klaudia!B53 -> 2:0 | BC24: =Klaudia!B54 -> 2:0 | BD24: =Klaudia!B55 -> 1:1 | BE24: =Klaudia!B56 -> 0:2 | BF24: =Klaudia!B57 -> 1:3 | BG24: =Klaudia!B58 -> 1:1 | BH24: =Klaudia!B59 -> 0:2 | BI24: =Klaudia!B60 -> 1:2 | BJ24: =Klaudia!B61 -> 1:1 | BK24: =Klaudia!B62 -> 1:3 | BL24: =Klaudia!B63 -> 2:0 | BM24: =Klaudia!B64 -> 0:1 | BN24: =Klaudia!B65 -> 1:2 | BO24: =Klaudia!B66 -> 1:1 | BP24: =Klaudia!B67 -> 0:2 | BQ24: =Klaudia!B68 -> 0:3 | BR24: =Klaudia!B69 -> 2:1 | BS24: =Klaudia!B70 -> 1:1 | BT24: =Klaudia!B71 -> 1:1 | BU24: =Klaudia!B72 -> 1:1 | BV24: =Klaudia!B73 -> 0:3 | BW24: =Klaudia!D74 -> 1
A25: Magdalena | B25: =BW25 -> 1 | C25: =Magdalena!B2 -> 3:2 | D25: =Magdalena!B3 -> 2:2 | E25: =Magdalena!B4 -> 0:1 | F25: =Magdalena!B5 -> 2:1 | G25: =Magdalena!B6 -> 3:2 | H25: =Magdalena!B7 -> 4:0 | I25: =Magdalena!B8 -> 0:3 | J25: =Magdalena!B9 -> 2:2 | K25: =Magdalena!B10 -> 5:0 | L25: =Magdalena!B11 -> 3:1 | M25: =Magdalena!B12 -> 1:1 | N25: =Magdalena!B13 -> 4:1 | O25: =Magdalena!B14 -> 5:1 | P25: =Magdalena!B15 -> 3:1 | Q25: =Magdalena!B16 -> 1:2 | R25: =Magdalena!B17 -> 2:2 | S25: =Magdalena!B18 -> 3:1 | T25: =Magdalena!B19 -> 0:4 | U25: =Magdalena!B20 -> 4:1 | V25: =Magdalena!B21 -> 2:0 | W25: =Magdalena!B22 -> 3:0 | X25: =Magdalena!B23 -> 2:2 | Y25: =Magdalena!B24 -> 3:2 | Z25: =Magdalena!B25 -> 3:3 | AA25: =Magdalena!B26 -> 3:1 | AB25: =Magdalena!B27 -> 2:1 | AC25: =Magdalena!B28 -> 3:1 | AD25: =Magdalena!B29 -> 5:2 | AE25: =Magdalena!B30 -> 3:1 | AF25: =Magdalena!B31 -> 3:0 | AG25: =Magdalena!B32 -> 4:0 | AH25: =Magdalena!B33 -> 2:1 | AI25: =Magdalena!B34 -> 2:2 | AJ25: =Magdalena!B35 -> 5:1 | AK25: =Magdalena!B36 -> 2:1 | AL25: =Magdalena!B37 -> 1:3 | AM25: =Magdalena!B38 -> 4:2 | AN25: =Magdalena!B39 -> 1:0 | AO25: =Magdalena!B40 -> 2:1 | AP25: =Magdalena!B41 -> 1:0 | AQ25: =Magdalena!B42 -> 3:2 | AR25: =Magdalena!B43 -> 5:2 | AS25: =Magdalena!B44 -> 3:0 | AT25: =Magdalena!B45 -> 0:1 | AU25: =Magdalena!B46 -> 4:0 | AV25: =Magdalena!B47 -> 3:1 | AW25: =Magdalena!B48 -> 0:1 | AX25: =Magdalena!B49 -> 1:0 | AY25: =Magdalena!B50 -> 1:1 | AZ25: =Magdalena!B51 -> 1:0 | BA25: =Magdalena!B52 -> 2:4 | BB25: =Magdalena!B53 -> 1:0 | BC25: =Magdalena!B54 -> 1:1 | BD25: =Magdalena!B55 -> 1:0 | BE25: =Magdalena!B56 -> 1:2 | BF25: =Magdalena!B57 -> 3:4 | BG25: =Magdalena!B58 -> 2:1 | BH25: =Magdalena!B59 -> 1:2 | BI25: =Magdalena!B60 -> 1:1 | BJ25: =Magdalena!B61 -> 1:2 | BK25: =Magdalena!B62 -> 1:4 | BL25: =Magdalena!B63 -> 0:1 | BM25: =Magdalena!B64 -> 1:0 | BN25: =Magdalena!B65 -> 1:4 | BO25: =Magdalena!B66 -> 2:1 | BP25: =Magdalena!B67 -> 2:3 | BQ25: =Magdalena!B68 -> 1:2 | BR25: =Magdalena!B69 -> 2:1 | BS25: =Magdalena!B70 -> 2:5 | BT25: =Magdalena!B71 -> 1:2 | BU25: =Magdalena!B72 -> 1:2 | BV25: =Magdalena!B73 -> 0:1 | BW25: =Magdalena!D74 -> 1
A26: Monika SP | B26: =BW26 -> 1 | C26: ='Monika SP'!B2 -> 3:0 | D26: ='Monika SP'!B3 -> 1:2 | E26: ='Monika SP'!B4 -> 2:0 | F26: ='Monika SP'!B5 -> 1:0 | G26: ='Monika SP'!B6 -> 0:2 | H26: ='Monika SP'!B7 -> 2:0 | I26: ='Monika SP'!B8 -> 1:3 | J26: ='Monika SP'!B9 -> 1:2 | K26: ='Monika SP'!B10 -> 3:0 | L26: ='Monika SP'!B11 -> 2:0 | M26: ='Monika SP'!B12 -> 1:3 | N26: ='Monika SP'!B13 -> 2:0 | O26: ='Monika SP'!B14 -> 3:0 | P26: ='Monika SP'!B15 -> 2:1 | Q26: ='Monika SP'!B16 -> 2:0 | R26: ='Monika SP'!B17 -> 1:2 | S26: ='Monika SP'!B18 -> 3:0 | T26: ='Monika SP'!B19 -> 0:2 | U26: ='Monika SP'!B20 -> 3:0 | V26: ='Monika SP'!B21 -> 2:1 | W26: ='Monika SP'!B22 -> 3:0 | X26: ='Monika SP'!B23 -> 2:1 | Y26: ='Monika SP'!B24 -> 1:2 | Z26: ='Monika SP'!B25 -> 0:3 | AA26: ='Monika SP'!B26 -> 2:1 | AB26: ='Monika SP'!B27 -> 2:0 | AC26: ='Monika SP'!B28 -> 2:1 | AD26: ='Monika SP'!B29 -> 3:1 | AE26: ='Monika SP'!B30 -> 2:1 | AF26: ='Monika SP'!B31 -> 1:2 | AG26: ='Monika SP'!B32 -> 3:0 | AH26: ='Monika SP'!B33 -> 2:0 | AI26: ='Monika SP'!B34 -> 3:1 | AJ26: ='Monika SP'!B35 -> 3:0 | AK26: ='Monika SP'!B36 -> 2:0 | AL26: ='Monika SP'!B37 -> 1:2 | AM26: ='Monika SP'!B38 -> 2:1 | AN26: ='Monika SP'!B39 -> 2:0 | AO26: ='Monika SP'!B40 -> 2:0 | AP26: ='Monika SP'!B41 -> 0:2 | AQ26: ='Monika SP'!B42 -> 2:0 | AR26: ='Monika SP'!B43 -> 3:0 | AS26: ='Monika SP'!B44 -> 2:1 | AT26: ='Monika SP'!B45 -> 2:3 | AU26: ='Monika SP'!B46 -> 3:0 | AV26: ='Monika SP'!B47 -> 2:0 | AW26: ='Monika SP'!B48 -> 1:2 | AX26: ='Monika SP'!B49 -> 2:0 | AY26: ='Monika SP'!B50 -> 2:1 | AZ26: ='Monika SP'!B51 -> 1:2 | BA26: ='Monika SP'!B52 -> 1:3 | BB26: ='Monika SP'!B53 -> 2:0 | BC26: ='Monika SP'!B54 -> 2:1 | BD26: ='Monika SP'!B55 -> 2:1 | BE26: ='Monika SP'!B56 -> 2:0 | BF26: ='Monika SP'!B57 -> 1:3 | BG26: ='Monika SP'!B58 -> 1:2 | BH26: ='Monika SP'!B59 -> 0:2 | BI26: ='Monika SP'!B60 -> 1:2 | BJ26: ='Monika SP'!B61 -> 1:2 | BK26: ='Monika SP'!B62 -> 1:3 | BL26: ='Monika SP'!B63 -> 2:1 | BM26: ='Monika SP'!B64 -> 0:2 | BN26: ='Monika SP'!B65 -> 0:2 | BO26: ='Monika SP'!B66 -> 2:0 | BP26: ='Monika SP'!B67 -> 1:3 | BQ26: ='Monika SP'!B68 -> 0:3 | BR26: ='Monika SP'!B69 -> 2:0 | BS26: ='Monika SP'!B70 -> 1:2 | BT26: ='Monika SP'!B71 -> 2:0 | BU26: ='Monika SP'!B72 -> 0:2 | BV26: ='Monika SP'!B73 -> 0:3 | BW26: ='Monika SP'!D74 -> 1
A27: Przemek | B27: =BW27 -> 1 | C27: =Przemek!B2 -> 2:1 | D27: =Przemek!B3 -> 1:1 | E27: =Przemek!B4 -> 3:1 | F27: =Przemek!B5 -> 2:1 | G27: =Przemek!B6 -> 0:3 | H27: =Przemek!B7 -> 2:1 | I27: =Przemek!B8 -> 0:4 | J27: =Przemek!B9 -> 1:3 | K27: =Przemek!B10 -> 5:0 | L27: =Przemek!B11 -> 3:1 | M27: =Przemek!B12 -> 2:2 | N27: =Przemek!B13 -> 1:0 | O27: =Przemek!B14 -> 4:0 | P27: =Przemek!B15 -> 3:2 | Q27: =Przemek!B16 -> 1:2 | R27: =Przemek!B17 -> 1:1 | S27: =Przemek!B18 -> 3:1 | T27: =Przemek!B19 -> 1:5 | U27: =Przemek!B20 -> 3:0 | V27: =Przemek!B21 -> 2:0 | W27: =Przemek!B22 -> 2:0 | X27: =Przemek!B23 -> 2:1 | Y27: =Przemek!B24 -> 2:1 | Z27: =Przemek!B25 -> 0:3 | AA27: =Przemek!B26 -> 1:0 | AB27: =Przemek!B27 -> 2:1 | AC27: =Przemek!B28 -> 2:0 | AD27: =Przemek!B29 -> 2:1 | AE27: =Przemek!B30 -> 2:2 | AF27: =Przemek!B31 -> 1:1 | AG27: =Przemek!B32 -> 3:0 | AH27: =Przemek!B33 -> 2:1 | AI27: =Przemek!B34 -> 3:2 | AJ27: =Przemek!B35 -> 2:1 | AK27: =Przemek!B36 -> 3:0 | AL27: =Przemek!B37 -> 1:1 | AM27: =Przemek!B38 -> 2:1 | AN27: =Przemek!B39 -> 3:1 | AO27: =Przemek!B40 -> 4:1 | AP27: =Przemek!B41 -> 0:1 | AQ27: =Przemek!B42 -> 2:1 | AR27: =Przemek!B43 -> 3:0 | AS27: =Przemek!B44 -> 2:1 | AT27: =Przemek!B45 -> 0:2 | AU27: =Przemek!B46 -> 3:0 | AV27: =Przemek!B47 -> 2:1 | AW27: =Przemek!B48 -> 0:2 | AX27: =Przemek!B49 -> 1:0 | AY27: =Przemek!B50 -> 2:1 | AZ27: =Przemek!B51 -> 2:0 | BA27: =Przemek!B52 -> 1:3 | BB27: =Przemek!B53 -> 3:0 | BC27: =Przemek!B54 -> 1:2 | BD27: =Przemek!B55 -> 1:1 | BE27: =Przemek!B56 -> 0:3 | BF27: =Przemek!B57 -> 1:3 | BG27: =Przemek!B58 -> 1:2 | BH27: =Przemek!B59 -> 1:3 | BI27: =Przemek!B60 -> 2:1 | BJ27: =Przemek!B61 -> 1:1 | BK27: =Przemek!B62 -> 2:2 | BL27: =Przemek!B63 -> 3:1 | BM27: =Przemek!B64 -> 2:1 | BN27: =Przemek!B65 -> 2:3 | BO27: =Przemek!B66 -> 1:0 | BP27: =Przemek!B67 -> 0:2 | BQ27: =Przemek!B68 -> 0:4 | BR27: =Przemek!B69 -> 2:1 | BS27: =Przemek!B70 -> 1:1 | BT27: =Przemek!B71 -> 2:1 | BU27: =Przemek!B72 -> 1:2 | BV27: =Przemek!B73 -> 0:4 | BW27: =Przemek!D74 -> 1
